Workbook

Sheet README
A1: 국채선물 차익거래 실시간 모니터 ― 사용설명서
B3: 1. 이 파일이 계산하는 것
B4: 한국 국채선물은 실물인수도가 아닌 '현금결제' 상품이다. 최종결제기준가격은 최종거래일에 국고채전문딜러들이
B5: 제출한 바스켓(최종결제기준채권) 종목별 수익률을 집계·평균하여, 표면금리 5% / 6개월 이표 / 잔존 n년의
B6: '표준물(가상채권)' 할인율로 적용해 산출한다. 따라서 차익거래 손익은 다음과 같이 분해된다.
B8: 만기손익 = [선물 leg] (진입가 − 표준물가격(바스켓 평균수익률)) × 1포인트가치 × 계약수 × 방향
B9: + [현물 leg] Σ (만기 처분단가 − 선도 목표단가) / 100 × 보유액면 × 방향
B10: − 거래비용
B12: 선도 목표단가 = 현물단가 + 조달이자 − 기간중 쿠폰 재투자원리금 (= 캐리 반영 선도가격)
B13: 각 종목의 선도 BPV 기준으로 헤지액면을 잡으면 [현물 leg]가 수익률 변동을 상쇄하여,
B14: 만기손익 ≈ 순베이시스(= 시장선물가 − 이론선물가) × 1포인트가치 − 비용 으로 '락인'된다.
B15: 2. 사용 순서
B16: ① [실시간] 시트의 붉은 글씨 셀에 사용 중인 데이터 벤더의 RTD/DDE 수식을 붙여넣는다. (→ 연동가이드 시트)
... B40: · 초기 입력값(바스켓 종목, 수익률, 선물가격, 조달금리)은 형식 예시용 더미 데이터이며 실거래 값이 아니다.

Sheet 실시간
A1: 실시간 데이터 연결 시트 ― 붉은 셀에 벤더 RTD/DDE 수식을 붙여넣으세요
A3: 항목 | B3: 종목코드/심볼 | C3: 값 | D3: 연동 수식 예시 (연합인포맥스) | E3: 비고
A5: 국채선물 현재가 | B5: KTB10 최근월물 | C5: 117.52 | D5: =IMFX("F 10YKTB","현재가") | E5: 가격 100 기준
A6: 국채선물 매수1호가(Bid) | B6: KTB10 최근월물 | C6: 117.51 | D6: =IMFX("F 10YKTB","매수1호가") | E6: 선물 매도 시 체결가
A7: 국채선물 매도1호가(Ask) | B7: KTB10 최근월물 | C7: 117.53 | D7: =IMFX("F 10YKTB","매도1호가") | E7: 선물 매수 시 체결가
A8: 국채선물 미드 | C8: =AVERAGE(C6:C7) | D8: =AVERAGE(C6:C7) | E8: 자동계산
A10: 바스켓1 Bid수익률(딜러매수) | B10: KR103502GE97 | C10: 2.96 | D10: =IMFX("KR103502GE97","매수수익률") | E10: 내가 매도할 때 적용 (%)
A11: 바스켓1 Ask수익률(딜러매도) | B11: KR103502GE97 | C11: 2.95 | D11: =IMFX("KR103502GE97","매도수익률") | E11: 내가 매수할 때 적용 (%)
A12: 바스켓2 Bid수익률(딜러매수) | B12: KR103503GF95 | C12: 2.97 | D12: =IMFX("KR103503GF95","매수수익률") | E12: (%)
A13: 바스켓2 Ask수익률(딜러매도) | B13: KR103503GF95 | C13: 2.96 | D13: =IMFX("KR103503GF95","매도수익률") | E13: (%)
A14: 바스켓3 Bid수익률(딜러매수) | B14: KR103504GH93 | C14: 2.98 | D14: =IMFX("KR103504GH93","매수수익률") | E14: (%)
A15: 바스켓3 Ask수익률(딜러매도) | B15: KR103504GH93 | C15: 2.97 | D15: =IMFX("KR103504GH93","매도수익률") | E15: (%)
A17: RP(레포) 조달금리 | C17: 2.6 | D17: =IMFX("RP1D","금리") | E17: [설정]에서 '실시간' 선택 시 사용 (%)
A18: CD 91일 | C18: 2.75 | D18: =IMFX("CD91","금리") | E18: 참고 (%)
A19: 국고 3년 지표 | C19: 2.7 | D19: =IMFX("KTB3Y","수익률") | E19: 참고 (%)
A21: 갱신시각 | C21: =NOW()
A23: ※ 현재 들어있는 숫자는 형식 확인용 더미값입니다. 실거래 전 반드시 벤더 수식으로 교체하세요. 수식 예시는 [연동가이드] 시트 참조.
A24: ※ 채권 수익률은 '딜러 매수호가(Bid)=높은 수익률/낮은 가격', '딜러 매도호가(Ask)=낮은 수익률/높은 가격' 입니다. 내가 바스켓을 매수하면 Ask수익률이 체결 기준입니다.

Sheet 설정
A1: 설정 ― 노란 셀만 입력하십시오
A3: [1] 선물 계약 사양 | F3: ▼ 매핑표(수정금지)
A4: 대상 선물 | B4: 10년 | D4: 3년 / 5년 / 10년 / 30년 | F4: 3년 | G4: 3
A5: 표준물 만기 | B5: =IFERROR(VLOOKUP($B$4,$F$4:$G$7,2,FALSE),10) | C5: 년 | F5: 5년 | G5: 5
A6: 표준물 표면금리 | B6: 0.05 | D6: KRX 표준물 규격: 연 5% | F6: 10년 | G6: 10
A7: 이표주기 | B7: 2 | C7: 회/년 | D7: 6개월 이표 | F7: 30년 | G7: 30
A8: 거래단위(액면) | B8: 100000000 | C8: 원 | D8: KRX 명세 확인 필수
A9: 가격 1.00포인트 가치 | B9: =B8/100 | C9: 원
A10: 호가단위(틱) | B10: 0.01
A11: 1틱 가치 | B11: =B10*B9 | C11: 원
A13: [2] 결제 일정
A14: 결제 연도 | B14: 2026
A15: 결제 월 | B15: 9 | D15: 3 / 6 / 9 / 12
A16: 최종거래일(자동: 세번째 화요일) | B16: =DATE(B14,B15,1)+MOD(2-WEEKDAY(DATE(B14,B15,1),2)+7,7)+14
A17: 최종거래일(수동 override) | D17: 공휴일 등으로 조정 시 입력
A18: ▶ 적용 최종거래일 | B18: =IF(B17="",B16,B17)
A19: 최종결제일(자동: 익영업일) | B19: =WORKDAY(B18,1)
A20: 최종결제일(수동 override)
A21: ▶ 적용 최종결제일 (H) | B21: =IF(B20="",B19,B20) | D21: 현물 청산 결제일 = 손익 확정 시점
A23: [3] 평가일 / 금리
A24: 평가일(오늘) | B24: =TODAY()
A25: 현물 결제일(자동: T+1) | B25: =WORKDAY(B24,1) | D25: 국고채 장외 익일결제 관행
A26: 현물 결제일(수동 override)
A27: ▶ 적용 현물결제일 (S0) | B27: =IF(B26="",B25,B26)
A28: 보유일수 (S0 → H) | B28: =B21-B27 | C28: 일
A29: 조달금리 소스 | B29: 수동 | D29: 수동 / 실시간
A30: 조달금리(수동) | B30: 2.6 | C30: % | D30: 레포(RP) 실효 조달금리
A31: ▶ 적용 조달금리 | B31: =IF(B29="실시간",실시간!C17,B30) | C31: %
A32: 적용 조달금리(소수) | B32: =B31/100
A33: 쿠폰 재투자금리 | B33: =B31 | C33: % | D33: 기본: 조달금리와 동일
A34: 적용 재투자금리(소수) | B34: =B33/100
A35: 이자 일수기준 | B35: 365 | C35: 일 | D35: actual/365 단리
A37: [4] 포지션 / 헤지
A38: 포지션 방향 | B38: 선물매도+현물매수 | D38: 선물매도+현물매수 / 선물매수+현물매도
A39: 방향계수 | B39: =IF(B38="선물매도+현물매수",1,-1)
A40: 계약수 (Q) | B40: 10 | C40: 계약
A41: 선물 진입가격 | D41: 미입력 시 현재가 사용
A42: ▶ 적용 선물 진입가 | B42: =IF(B41="",실시간!C5,B41)
A43: 진입일 | D43: 미입력 시 오늘
A44: ▶ 적용 진입일 | B44: =IF(B43="",B24,B43)
...

Sheet 바스켓
A1: 바스켓 채권 (최종결제기준채권) ― 노란 셀 입력
A3: 항목 | B3: 단위 | C3: 종목1 | D3: 종목2 | E3: 종목3 | F3: 합계/검증 | G3: 비고
A4: 종목코드 | C4: KR103502GE97 | D4: KR103503GF95 | E4: KR103504GH93
A5: 종목명 | C5: 국고03000-3506(25-3) | D5: 국고02875-3509(25-6) | E5: 국고03125-3512(25-9)
A6: 발행일 | C6: 45818 | D6: 45910 | E6: 46001 | G6: 이표일 생성 기준
A7: 만기일 | C7: 49470 | D7: 49562 | E7: 49653 | G7: 이표일을 만기에서 6개월씩 역산
A8: 표면금리 | B8: % | C8: 3 | D8: 2.875 | E8: 3.125
A9: 이표주기 | B9: 회/년 | C9: 2 | D9: 2 | E9: 2
A10: 가중치 w | C10: =1/3 | D10: =1/3 | E10: =1/3 | F10: =SUM(C10:E10) | G10: KRX 최종결제기준가격은 종목별 수익률의 단순평균 → 기본 1/3. 미사용 종목은 0
A12: [실시간 수익률]
A13: Bid 수익률 (딜러 매수호가) | B13: % | C13: =실시간!C10 | D13: =실시간!C12 | E13: =실시간!C14
A14: Ask 수익률 (딜러 매도호가) | B14: % | C14: =실시간!C11 | D14: =실시간!C13 | E14: =실시간!C15
A15: Mid 수익률 | B15: % | C15: =AVERAGE(C13:C14) | D15: =AVERAGE(D13:D14) | E15: =AVERAGE(E13:E14)
A16: ▶ 적용 수익률 | B16: % | C16: =IF(설정!$B$46="미드",C15,IF(설정!$B$39=1,C14,C13)) | D16: =IF(설정!$B$46="미드",D15,IF(설정!$B$39=1,D14,D13)) | E16: =IF(설정!$B$46="미드",E15,IF(설정!$B$39=1,E14,E13)) | G16: 현물 매수(방향=1)면 Ask, 매도면 Bid 적용
A17: 적용 수익률(소수) | C17: =C16/100 | D17: =D16/100 | E17: =E16/100
A19: [현물 평가 — 결제일 S0]
A20: 잔존 이표 횟수 | B20: 회 | C20: =현금흐름!$B$79 | D20: =현금흐름!$AR$79 | E20: =현금흐름!$CH$79
A21: 다음 이표일 | C21: =현금흐름!$B$80 | D21: =현금흐름!$AR$80 | E21: =현금흐름!$CH$80
A22: 직전 이표일 | C22: =현금흐름!$B$81 | D22: =현금흐름!$AR$81 | E22: =현금흐름!$CH$81
A23: d (결제일→다음이표일) | B23: 일 | C23: =현금흐름!$B$82 | D23: =현금흐름!$AR$82 | E23: =현금흐름!$CH$82
A24: T (이표기간 일수) | B24: 일 | C24: =현금흐름!$B$83 | D24: =현금흐름!$AR$83 | E24: =현금흐름!$CH$83
A25: ▶ 단가 (더티, 100 기준) | C25: =현금흐름!$B$85 | D25: =현금흐름!$AR$85 | E25: =현금흐름!$CH$85
A26: 경과이자 (참고) | C26: =현금흐름!$B$91 | D26: =현금흐름!$AR$91 | E26: =현금흐름!$CH$91
A27: 클린가 (참고) | C27: =현금흐름!$B$92 | D27: =현금흐름!$AR$92 | E27: =현금흐름!$CH$92
A28: 현물 BPV | B28: 포인트/1bp | C28: =현금흐름!$B$88 | D28: =현금흐름!$AR$88 | E28: =현금흐름!$CH$88
A29: 현물 BPV (액면 1억 기준) | B29: 원/1bp | C29: =C28*설정!$B$9 | D29: =D28*설정!$B$9 | E29: =E28*설정!$B$9
A30: 수정듀레이션 | B30: 년 | C30: =현금흐름!$B$89 | D30: =현금흐름!$AR$89 | E30: =현금흐름!$CH$89
A32: [선도 평가 — 최종결제일 H]
A33: 보유일수 (S0→H) | B33: 일 | C33: =설정!$B$28 | D33: =설정!$B$28 | E33: =설정!$B$28
A34: 기간중 쿠폰 재투자FV | C34: =현금흐름!$B$100 | D34: =현금흐름!$AR$100 | E34: =현금흐름!$CH$100
A35: 조달이자 | C35: =현금흐름!$B$102 | D35: =현금흐름!$AR$102 | E35: =현금흐름!$CH$102
A36: ▶ 선도 목표단가 (더티) | C36: =현금흐름!$B$103 | D36: =현금흐름!$AR$103 | E36: =현금흐름!$CH$103 | G36: 현물단가 + 조달이자 − 쿠폰FV
A37: ▶ 선도 수익률 | B37: % | C37: =현금흐름!$B$111*100 | D37: =현금흐름!$AR$111*100 | E37: =현금흐름!$CH$111*100
A38: 수렴 잔차 (0에 근접해야 정상) | C38: =현금흐름!$B$113 | D38: =현금흐름!$AR$113 | E38: =현금흐름!$CH$113
A39: 선도 BPV | B39: 포인트/1bp | C39: =현금흐름!$B$116 | D39: =현금흐름!$AR$116 | E39: =현금흐름!$CH$116
A40: 선도 BPV (액면 1억 기준) | B40: 원/1bp | C40: =C39*설정!$B$9 | D40: =D39*설정!$B$9 | E40: =E39*설정!$B$9
A41: 선도 2차미분 P'' | C41: =현금흐름!$B$117 | D41: =현금흐름!$AR$117 | E41: =현금흐름!$CH$117
A42: 선도 잔존만기 | B42: 년 | C42: =현금흐름!$B$118 | D42: =현금흐름!$AR$118 | E42: =현금흐름!$CH$118
A43: 캐리 (선도−현물) | B43: bp | C43: =(C37-C16)*100 | D43: =(D37-D16)*100 | E43: =(E37-E16)*100 | G43: 양수 = 선도수익률이 높음 = 네거티브 캐리
A45: [헤지 / 포지션]
...

Sheet 이론가
A1: 이론 선물가격 · 베이시스 · 차익 판정
A3: [1] 바스켓 선도수익률 | C3: 가중치
A4: 종목1 선도수익률 | B4: =바스켓!C37 | C4: =바스켓!C10
A5: 종목2 선도수익률 | B5: =바스켓!D37 | C5: =바스켓!D10
A6: 종목3 선도수익률 | B6: =바스켓!E37 | C6: =바스켓!E10
A7: ▶ 가중평균 선도수익률 | B7: =SUMPRODUCT(B4:B6,C4:C6)/SUM(C4:C6) | C7: %
A8: (소수) | B8: =B7/100
A10: [2] 표준물 가격 = 최종결제기준가격 산식
A11: 표준물 만기 | B11: =설정!$B$5 | C11: 년
A12: 반기 기간수 N | B12: =B11*설정!$B$7
A13: 반기 쿠폰 | B13: =설정!$B$6*100/설정!$B$7
A14: ▶ 이론 선물가격 | B14: =(설정!$B$6*100/($B$8))*(1-(1/(1+($B$8)/2))^$B$12)+100*(1/(1+($B$8)/2))^$B$12
A15: 이론가 (호가단위 반올림) | B15: =ROUND(B14/설정!$B$10,0)*설정!$B$10
A16: P(ȳ+1bp) | B16: =(설정!$B$6*100/($B$8+0.0001))*(1-(1/(1+($B$8+0.0001)/2))^$B$12)+100*(1/(1+($B$8+0.0001)/2))^$B$12
A17: P(ȳ−1bp) | B17: =(설정!$B$6*100/($B$8-0.0001))*(1-(1/(1+($B$8-0.0001)/2))^$B$12)+100*(1/(1+($B$8-0.0001)/2))^$B$12
A18: ▶ 표준물 BPV | B18: =(B17-B16)/2 | C18: 포인트/1bp
A19: 표준물 BPV (원/1bp/계약) | B19: =B18*설정!$B$9 | C19: 원
A20: 표준물 수정듀레이션 | B20: =B18*10000/B14 | C20: 년
A22: [3] 시장 선물가격 → 내재수익률 (뉴턴 2회)
A23: 시장 선물가격 | B23: =실시간!C5
A24: ya (초기값) | B24: =B8
A25: P(ya) | B25: =B14
A26: |dP/dy| | B26: =B18*10000
A27: yb | B27: =B24+(B25-B23)/B26
A28: P(yb) | B28: =(설정!$B$6*100/($B$27))*(1-(1/(1+($B$27)/2))^$B$12)+100*(1/(1+($B$27)/2))^$B$12
A29: yc | B29: =B27+(B28-B23)/B26
A30: P(yc) | B30: =(설정!$B$6*100/($B$29))*(1-(1/(1+($B$29)/2))^$B$12)+100*(1/(1+($B$29)/2))^$B$12
A31: ▶ 선물 내재수익률 | B31: =B29*100 | C31: %
A32: 수렴 잔차 | B32: =B30-B23
A34: [4] 베이시스 및 차익 판정
A35: ▶ 베이시스 (시장가 − 이론가) | B35: =B23-B14 | C35: 포인트
A36: 베이시스 | B36: =B35/설정!$B$10 | C36: 틱
A37: ▶ 베이시스 | B37: =B35*설정!$B$9 | C37: 원/계약
A38: 수익률 스프레드 (선도평균 − 내재) | B38: =(B7-B31)*100 | C38: bp | D38: 양수 = 선물 고평가
A39: 총 거래비용 | B39: =설정!$B$53 | C39: 원/계약
A40: ▶ 순차익 (비용 차감후) | B40: =ABS(B37)-B39 | C40: 원/계약
A41: 계약수 | B41: =설정!$B$40 | C41: 계약
A42: ▶ 총 순차익 | B42: =B40*B41 | C42: 원
A43: 권장 포지션 | B43: =IF(B37>0,"선물 매도 + 바스켓 매수 (선물 고평가)",IF(B37<0,"선물 매수 + 바스켓 매도 (선물 저평가)","중립"))
A44: 설정된 방향과 일치? | B44: =IF(OR(AND(B37>0,설정!$B$39=1),AND(B37<0,설정!$B$39=-1)),"○ 일치","✕ 설정!B38 방향 확인")
...

Sheet 손익
A1: 만기 손익 ― 바스켓 1단위 = 선물 1계약 대응
A3: [A] 실시간 락인 손익 (지금 진입 → 만기 보유 가정)
A4: 베이시스 | B4: =이론가!B37 | C4: 원/계약
A5: 총 거래비용 | B5: =설정!$B$53 | C5: 원/계약
A6: ▶ 순차익 | B6: =이론가!B40 | C6: 원/계약
A7: 계약수 Q | B7: =설정!$B$40 | C7: 계약
A8: ▶ 총 순차익 | B8: =B6*B7 | C8: 원
A9: 바스켓 투자금액 (현물 매입액) | B9: =SUM(바스켓!C53:E53) | C9: 원
A10: 보유일수 | B10: =설정!$B$28 | C10: 일
A11: ▶ 연환산 수익률 | B11: =IF(AND(B9>0,B10>0),B8/B9*365/B10*100,"") | C11: %
A12: 조달금리 대비 초과 | B12: =IF(B11="","",B11-설정!$B$31) | C12: %p | D12: 레포로 100% 조달 시 이 값이 순마진
A14: [B] 현재 미실현 손익 (보유 포지션 마킹)
A15: 선물 진입가 | B15: =설정!$B$42
A16: 선물 현재가 | B16: =실시간!C5
A17: 선물 평가손익 | B17: =(B15-B16)*설정!$B$39*설정!$B$9*설정!$B$40 | C17: 원
A18: 현물 평가손익 | B18: =바스켓!F54 | C18: 원
A19: 진입 경과일수 | B19: =MAX(0,설정!$B$27-설정!$B$44) | C19: 일
A20: 경과 조달이자 | B20: =-바스켓!F51*설정!$B$32*B19/365*설정!$B$39 | C20: 원
A21: ▶ 미실현 손익 합계 | B21: =B17+B18+B20 | C21: 원
A23: [C] 만기 손익 — 시나리오
A24: 만기 수익률 평행이동 | B24: 0 | C24: bp | D24: 만기시점 바스켓 수익률 shift
A25: 만기 바스켓 평균수익률 | B25: =이론가!B7+B24/100 | C25: %
A26: ▶ 최종결제기준가격 | B26: =(설정!$B$6*100/($B$25/100))*(1-(1/(1+($B$25/100)/2))^이론가!$B$12)+100*(1/(1+($B$25/100)/2))^이론가!$B$12
A27: 종목1 만기 단가(더티) | B27: =현금흐름!$B$121 | D27: 이표 스케줄 전체를 재할인한 정밀 재평가값 (근사 없음)
A28: 종목2 만기 단가(더티) | B28: =현금흐름!$AR$121 | D28: 이표 스케줄 전체를 재할인한 정밀 재평가값 (근사 없음)
A29: 종목3 만기 단가(더티) | B29: =현금흐름!$CH$121 | D29: 이표 스케줄 전체를 재할인한 정밀 재평가값 (근사 없음)
A31: ── C-1. 현재 시장가로 신규 진입한다고 가정 ──
A32: 선물 leg | B32: =(이론가!B23-B26)*설정!$B$39*설정!$B$9*설정!$B$40 | C32: 원
A33: 현물 leg | B33: =설정!$B$39*(($B$27-바스켓!C36)/100*바스켓!C49+($B$28-바스켓!D36)/100*바스켓!D49+($B$29-바스켓!E36)/100*바스켓!E49) | C33: 원 | D33: 선도 목표단가 대비 처분손익. 조달이자·쿠폰FV는 선도단가에 이미 반영됨
A34: 거래비용 | B34: =-설정!$B$53*설정!$B$40 | C34: 원
A35: ▶ 순 만기손익 | B35: =B32+B33+B34 | C35: 원
A36: ▶ 바스켓 1단위당 (=계약당) | B36: =IFERROR(B35/설정!$B$40,0) | C36: 원
A37: ▶ 액면 1억원당 | B37: =B36 | C37: 원
A39: ── C-2. 실제 보유 포지션 기준 ──
A40: 선물 leg | B40: =(설정!$B$42-B26)*설정!$B$39*설정!$B$9*설정!$B$40 | C40: 원
A41: 현물 취득금액 | B41: =바스켓!F51 | C41: 원
A42: 조달일수 (진입일→H) | B42: =MAX(0,설정!$B$21-설정!$B$44) | C42: 일
A43: 조달 원리금 상환 | B43: =-B41*(1+설정!$B$32*B42/365) | C43: 원
A44: 만기 처분금액 | B44: =$B$27/100*바스켓!C49+$B$28/100*바스켓!D49+$B$29/100*바스켓!E49 | C44: 원
A45: 쿠폰 재투자 수입 | B45: =바스켓!C34/100*바스켓!C49+바스켓!D34/100*바스켓!D49+바스켓!E34/100*바스켓!E49 | C45: 원
...

Sheet 시나리오
A1: 만기 손익 민감도 ― 바스켓 수익률 평행이동 (헤지 유효성 점검)
A3: shift (bp) | B3: 만기 평균수익률(%) | C3: 최종결제가격 | D3: 선물 leg (원) | E3: 현물 leg (원) | F3: 거래비용 (원) | G3: 순 만기손익 (원) | H3: 바스켓 1단위당 (원)
A4: -100 | B4: =이론가!$B$7+$A4/100 | C4: =(설정!$B$6*100/($B4/100))*(1-(1/(1+($B4/100)/2))^이론가!$B$12)+100*(1/(1+($B4/100)/2))^이론가!$B$12 | D4: =(이론가!$B$23-$C4)*설정!$B$39*설정!$B$9*설정!$B$40 | E4: =설정!$B$39*((현금흐름!$B$123-바스켓!C36)/100*바스켓!C49+(현금흐름!$AR$123-바스켓!D36)/100*바스켓!D49+(현금흐름!$CH$123-바스켓!E36)/100*바스켓!E49) | F4: =-설정!$B$53*설정!$B$40 | G4: =$D4+$E4+$F4 | H4: =IFERROR($G4/설정!$B$40,0)
A5: -90 | B5: =이론가!$B$7+$A5/100 | C5: =(설정!$B$6*100/($B5/100))*(1-(1/(1+($B5/100)/2))^이론가!$B$12)+100*(1/(1+($B5/100)/2))^이론가!$B$12 | D5: =(이론가!$B$23-$C5)*설정!$B$39*설정!$B$9*설정!$B$40 | E5: =설정!$B$39*((현금흐름!$B$124-바스켓!C36)/100*바스켓!C49+(현금흐름!$AR$124-바스켓!D36)/100*바스켓!D49+(현금흐름!$CH$124-바스켓!E36)/100*바스켓!E49) | F5: =-설정!$B$53*설정!$B$40 | G5: =$D5+$E5+$F5 | H5: =IFERROR($G5/설정!$B$40,0)
A6: -80 | B6: =이론가!$B$7+$A6/100 | C6: =(설정!$B$6*100/($B6/100))*(1-(1/(1+($B6/100)/2))^이론가!$B$12)+100*(1/(1+($B6/100)/2))^이론가!$B$12 | D6: =(이론가!$B$23-$C6)*설정!$B$39*설정!$B$9*설정!$B$40 | E6: =설정!$B$39*((현금흐름!$B$125-바스켓!C36)/100*바스켓!C49+(현금흐름!$AR$125-바스켓!D36)/100*바스켓!D49+(현금흐름!$CH$125-바스켓!E36)/100*바스켓!E49) | F6: =-설정!$B$53*설정!$B$40 | G6: =$D6+$E6+$F6 | H6: =IFERROR($G6/설정!$B$40,0)
A7: -70 | B7: =이론가!$B$7+$A7/100 | C7: =(설정!$B$6*100/($B7/100))*(1-(1/(1+($B7/100)/2))^이론가!$B$12)+100*(1/(1+($B7/100)/2))^이론가!$B$12 | D7: =(이론가!$B$23-$C7)*설정!$B$39*설정!$B$9*설정!$B$40 | E7: =설정!$B$39*((현금흐름!$B$126-바스켓!C36)/100*바스켓!C49+(현금흐름!$AR$126-바스켓!D36)/100*바스켓!D49+(현금흐름!$CH$126-바스켓!E36)/100*바스켓!E49) | F7: =-설정!$B$53*설정!$B$40 | G7: =$D7+$E7+$F7 | H7: =IFERROR($G7/설정!$B$40,0)
A8: -60 | B8: =이론가!$B$7+$A8/100 | C8: =(설정!$B$6*100/($B8/100))*(1-(1/(1+($B8/100)/2))^이론가!$B$12)+100*(1/(1+($B8/100)/2))^이론가!$B$12 | D8: =(이론가!$B$23-$C8)*설정!$B$39*설정!$B$9*설정!$B$40 | E8: =설정!$B$39*((현금흐름!$B$127-바스켓!C36)/100*바스켓!C49+(현금흐름!$AR$127-바스켓!D36)/100*바스켓!D49+(현금흐름!$CH$127-바스켓!E36)/100*바스켓!E49) | F8: =-설정!$B$53*설정!$B$40 | G8: =$D8+$E8+$F8 | H8: =IFERROR($G8/설정!$B$40,0)
A9: -50 | B9: =이론가!$B$7+$A9/100 | C9: =(설정!$B$6*100/($B9/100))*(1-(1/(1+($B9/100)/2))^이론가!$B$12)+100*(1/(1+($B9/100)/2))^이론가!$B$12 | D9: =(이론가!$B$23-$C9)*설정!$B$39*설정!$B$9*설정!$B$40 | E9: =설정!$B$39*((현금흐름!$B$128-바스켓!C36)/100*바스켓!C49+(현금흐름!$AR$128-바스켓!D36)/100*바스켓!D49+(현금흐름!$CH$128-바스켓!E36)/100*바스켓!E49) | F9: =-설정!$B$53*설정!$B$40 | G9: =$D9+$E9+$F9 | H9: =IFERROR($G9/설정!$B$40,0)
A10: -40 | B10: =이론가!$B$7+$A10/100 | C10: =(설정!$B$6*100/($B10/100))*(1-(1/(1+($B10/100)/2))^이론가!$B$12)+100*(1/(1+($B10/100)/2))^이론가!$B$12 | D10: =(이론가!$B$23-$C10)*설정!$B$39*설정!$B$9*설정!$B$40 | E10: =설정!$B$39*((현금흐름!$B$129-바스켓!C36)/100*바스켓!C49+(현금흐름!$AR$129-바스켓!D36)/100*바스켓!D49+(현금흐름!$CH$129-바스켓!E36)/100*바스켓!E49) | F10: =-설정!$B$53*설정!$B$40 | G10: =$D10+$E10+$F10 | H10: =IFERROR($G10/설정!$B$40,0)
A11: -30 | B11: =이론가!$B$7+$A11/100 | C11: =(설정!$B$6*100/($B11/100))*(1-(1/(1+($B11/100)/2))^이론가!$B$12)+100*(1/(1+($B11/100)/2))^이론가!$B$12 | D11: =(이론가!$B$23-$C11)*설정!$B$39*설정!$B$9*설정!$B$40 | E11: =설정!$B$39*((현금흐름!$B$130-바스켓!C36)/100*바스켓!C49+(현금흐름!$AR$130-바스켓!D36)/100*바스켓!D49+(현금흐름!$CH$130-바스켓!E36)/100*바스켓!E49) | F11: =-설정!$B$53*설정!$B$40 | G11: =$D11+$E11+$F11 | H11: =IFERROR($G11/설정!$B$40,0)
A12: -20 | B12: =이론가!$B$7+$A12/100 | C12: =(설정!$B$6*100/($B12/100))*(1-(1/(1+($B12/100)/2))^이론가!$B$12)+100*(1/(1+($B12/100)/2))^이론가!$B$12 | D12: =(이론가!$B$23-$C12)*설정!$B$39*설정!$B$9*설정!$B$40 | E12: =설정!$B$39*((현금흐름!$B$131-바스켓!C36)/100*바스켓!C49+(현금흐름!$AR$131-바스켓!D36)/100*바스켓!D49+(현금흐름!$CH$131-바스켓!E36)/100*바스켓!E49) | F12: =-설정!$B$53*설정!$B$40 | G12: =$D12+$E12+$F12 | H12: =IFERROR($G12/설정!$B$40,0)
A13: -10 | B13: =이론가!$B$7+$A13/100 | C13: =(설정!$B$6*100/($B13/100))*(1-(1/(1+($B13/100)/2))^이론가!$B$12)+100*(1/(1+($B13/100)/2))^이론가!$B$12 | D13: =(이론가!$B$23-$C13)*설정!$B$39*설정!$B$9*설정!$B$40 | E13: =설정!$B$39*((현금흐름!$B$132-바스켓!C36)/100*바스켓!C49+(현금흐름!$AR$132-바스켓!D36)/100*바스켓!D49+(현금흐름!$CH$132-바스켓!E36)/100*바스켓!E49) | F13: =-설정!$B$53*설정!$B$40 | G13: =$D13+$E13+$F13 | H13: =IFERROR($G13/설정!$B$40,0)
A14: 0 | B14: =이론가!$B$7+$A14/100 | C14: =(설정!$B$6*100/($B14/100))*(1-(1/(1+($B14/100)/2))^이론가!$B$12)+100*(1/(1+($B14/100)/2))^이론가!$B$12 | D14: =(이론가!$B$23-$C14)*설정!$B$39*설정!$B$9*설정!$B$40 | E14: =설정!$B$39*((현금흐름!$B$133-바스켓!C36)/100*바스켓!C49+(현금흐름!$AR$133-바스켓!D36)/100*바스켓!D49+(현금흐름!$CH$133-바스켓!E36)/100*바스켓!E49) | F14: =-설정!$B$53*설정!$B$40 | G14: =$D14+$E14+$F14 | H14: =IFERROR($G14/설정!$B$40,0)
A15: 10 | B15: =이론가!$B$7+$A15/100 | C15: =(설정!$B$6*100/($B15/100))*(1-(1/(1+($B15/100)/2))^이론가!$B$12)+100*(1/(1+($B15/100)/2))^이론가!$B$12 | D15: =(이론가!$B$23-$C15)*설정!$B$39*설정!$B$9*설정!$B$40 | E15: =설정!$B$39*((현금흐름!$B$134-바스켓!C36)/100*바스켓!C49+(현금흐름!$AR$134-바스켓!D36)/100*바스켓!D49+(현금흐름!$CH$134-바스켓!E36)/100*바스켓!E49) | F15: =-설정!$B$53*설정!$B$40 | G15: =$D15+$E15+$F15 | H15: =IFERROR($G15/설정!$B$40,0)
A16: 20 | B16: =이론가!$B$7+$A16/100 | C16: =(설정!$B$6*100/($B16/100))*(1-(1/(1+($B16/100)/2))^이론가!$B$12)+100*(1/(1+($B16/100)/2))^이론가!$B$12 | D16: =(이론가!$B$23-$C16)*설정!$B$39*설정!$B$9*설정!$B$40 | E16: =설정!$B$39*((현금흐름!$B$135-바스켓!C36)/100*바스켓!C49+(현금흐름!$AR$135-바스켓!D36)/100*바스켓!D49+(현금흐름!$CH$135-바스켓!E36)/100*바스켓!E49) | F16: =-설정!$B$53*설정!$B$40 | G16: =$D16+$E16+$F16 | H16: =IFERROR($G16/설정!$B$40,0)
A17: 30 | B17: =이론가!$B$7+$A17/100 | C17: =(설정!$B$6*100/($B17/100))*(1-(1/(1+($B17/100)/2))^이론가!$B$12)+100*(1/(1+($B17/100)/2))^이론가!$B$12 | D17: =(이론가!$B$23-$C17)*설정!$B$39*설정!$B$9*설정!$B$40 | E17: =설정!$B$39*((현금흐름!$B$136-바스켓!C36)/100*바스켓!C49+(현금흐름!$AR$136-바스켓!D36)/100*바스켓!D49+(현금흐름!$CH$136-바스켓!E36)/100*바스켓!E49) | F17: =-설정!$B$53*설정!$B$40 | G17: =$D17+$E17+$F17 | H17: =IFERROR($G17/설정!$B$40,0)
A18: 40 | B18: =이론가!$B$7+$A18/100 | C18: =(설정!$B$6*100/($B18/100))*(1-(1/(1+($B18/100)/2))^이론가!$B$12)+100*(1/(1+($B18/100)/2))^이론가!$B$12 | D18: =(이론가!$B$23-$C18)*설정!$B$39*설정!$B$9*설정!$B$40 | E18: =설정!$B$39*((현금흐름!$B$137-바스켓!C36)/100*바스켓!C49+(현금흐름!$AR$137-바스켓!D36)/100*바스켓!D49+(현금흐름!$CH$137-바스켓!E36)/100*바스켓!E49) | F18: =-설정!$B$53*설정!$B$40 | G18: =$D18+$E18+$F18 | H18: =IFERROR($G18/설정!$B$40,0)
A19: 50 | B19: =이론가!$B$7+$A19/100 | C19: =(설정!$B$6*100/($B19/100))*(1-(1/(1+($B19/100)/2))^이론가!$B$12)+100*(1/(1+($B19/100)/2))^이론가!$B$12 | D19: =(이론가!$B$23-$C19)*설정!$B$39*설정!$B$9*설정!$B$40 | E19: =설정!$B$39*((현금흐름!$B$138-바스켓!C36)/100*바스켓!C49+(현금흐름!$AR$138-바스켓!D36)/100*바스켓!D49+(현금흐름!$CH$138-바스켓!E36)/100*바스켓!E49) | F19: =-설정!$B$53*설정!$B$40 | G19: =$D19+$E19+$F19 | H19: =IFERROR($G19/설정!$B$40,0)
A20: 60 | B20: =이론가!$B$7+$A20/100 | C20: =(설정!$B$6*100/($B20/100))*(1-(1/(1+($B20/100)/2))^이론가!$B$12)+100*(1/(1+($B20/100)/2))^이론가!$B$12 | D20: =(이론가!$B$23-$C20)*설정!$B$39*설정!$B$9*설정!$B$40 | E20: =설정!$B$39*((현금흐름!$B$139-바스켓!C36)/100*바스켓!C49+(현금흐름!$AR$139-바스켓!D36)/100*바스켓!D49+(현금흐름!$CH$139-바스켓!E36)/100*바스켓!E49) | F20: =-설정!$B$53*설정!$B$40 | G20: =$D20+$E20+$F20 | H20: =IFERROR($G20/설정!$B$40,0)
A21: 70 | B21: =이론가!$B$7+$A21/100 | C21: =(설정!$B$6*100/($B21/100))*(1-(1/(1+($B21/100)/2))^이론가!$B$12)+100*(1/(1+($B21/100)/2))^이론가!$B$12 | D21: =(이론가!$B$23-$C21)*설정!$B$39*설정!$B$9*설정!$B$40 | E21: =설정!$B$39*((현금흐름!$B$140-바스켓!C36)/100*바스켓!C49+(현금흐름!$AR$140-바스켓!D36)/100*바스켓!D49+(현금흐름!$CH$140-바스켓!E36)/100*바스켓!E49) | F21: =-설정!$B$53*설정!$B$40 | G21: =$D21+$E21+$F21 | H21: =IFERROR($G21/설정!$B$40,0)
A22: 80 | B22: =이론가!$B$7+$A22/100 | C22: =(설정!$B$6*100/($B22/100))*(1-(1/(1+($B22/100)/2))^이론가!$B$12)+100*(1/(1+($B22/100)/2))^이론가!$B$12 | D22: =(이론가!$B$23-$C22)*설정!$B$39*설정!$B$9*설정!$B$40 | E22: =설정!$B$39*((현금흐름!$B$141-바스켓!C36)/100*바스켓!C49+(현금흐름!$AR$141-바스켓!D36)/100*바스켓!D49+(현금흐름!$CH$141-바스켓!E36)/100*바스켓!E49) | F22: =-설정!$B$53*설정!$B$40 | G22: =$D22+$E22+$F22 | H22: =IFERROR($G22/설정!$B$40,0)
A23: 90 | B23: =이론가!$B$7+$A23/100 | C23: =(설정!$B$6*100/($B23/100))*(1-(1/(1+($B23/100)/2))^이론가!$B$12)+100*(1/(1+($B23/100)/2))^이론가!$B$12 | D23: =(이론가!$B$23-$C23)*설정!$B$39*설정!$B$9*설정!$B$40 | E23: =설정!$B$39*((현금흐름!$B$142-바스켓!C36)/100*바스켓!C49+(현금흐름!$AR$142-바스켓!D36)/100*바스켓!D49+(현금흐름!$CH$142-바스켓!E36)/100*바스켓!E49) | F23: =-설정!$B$53*설정!$B$40 | G23: =$D23+$E23+$F23 | H23: =IFERROR($G23/설정!$B$40,0)
A24: 100 | B24: =이론가!$B$7+$A24/100 | C24: =(설정!$B$6*100/($B24/100))*(1-(1/(1+($B24/100)/2))^이론가!$B$12)+100*(1/(1+($B24/100)/2))^이론가!$B$12 | D24: =(이론가!$B$23-$C24)*설정!$B$39*설정!$B$9*설정!$B$40 | E24: =설정!$B$39*((현금흐름!$B$143-바스켓!C36)/100*바스켓!C49+(현금흐름!$AR$143-바스켓!D36)/100*바스켓!D49+(현금흐름!$CH$143-바스켓!E36)/100*바스켓!E49) | F24: =-설정!$B$53*설정!$B$40 | G24: =$D24+$E24+$F24 | H24: =IFERROR($G24/설정!$B$40,0)
A27: 손익 최대값 | B27: =MAX(G4:G24) | C27: 원
A28: 손익 최소값 | B28: =MIN(G4:G24) | C28: 원
A29: 변동폭 (헤지 잔여리스크) | B29: =B27-B28 | C29: 원
A30: 변동폭 ÷ shift0 손익 | B30: =IFERROR(B29/ABS(G14),0) | C30: 배
A31: shift 0 기준 손익 | B31: =G14 | C31: 원
A33: ※ BPV 헤지는 1차(듀레이션) 리스크만 중립화합니다. 위 표가 shift 0에서 볼록하게 꺾여 내려가는 것은 이 거래가 구조적으로 '컨벡시티 매도' 포지션이기 때문입니다 — 표준물(5% 쿠폰)이 바스켓(저쿠폰)보다 컨벡시티가 커서, 선물을 매도하면 컨벡시티를 파는 셈이 됩니다. 헤지로 제거되지 않습니다.
A34: ※ 평행이동만 가정합니다. 바스켓 종목 간 상대수익률(커브) 변화는 종목별 BPV 헤지로 이미 중립화되어 있습니다.
A35: ※ 현물 leg는 근사가 아니라 이표 스케줄 전체를 재할인한 정밀 재평가입니다. A열의 shift 값을 바꾸면 [현금흐름] 시트가 자동으로 해당 수익률에서 재평가합니다.

Sheet 현금흐름
A1: 현금흐름 스케줄 & 단가 계산 엔진 (직접 수정 금지)
A2: 만기일 | B2: =바스켓!C7 | AQ2: 만기일 | AR2: =바스켓!D7 | CG2: 만기일 | CH2: =바스켓!E7
A3: 발행일 | B3: =바스켓!C6 | AQ3: 발행일 | AR3: =바스켓!D6 | CG3: 발행일 | CH3: =바스켓!E6
A4: 표면금리(소수) | B4: =바스켓!C8/100 | AQ4: 표면금리(소수) | AR4: =바스켓!D8/100 | CG4: 표면금리(소수) | CH4: =바스켓!E8/100
A5: 반기 쿠폰액 | B5: =B4*100/바스켓!C9 | AQ5: 반기 쿠폰액 | AR5: =AR4*100/바스켓!D9 | CG5: 반기 쿠폰액 | CH5: =CH4*100/바스켓!E9
A6: 현물결제일 S0 | B6: =설정!$B$27 | AQ6: 현물결제일 S0 | AR6: =설정!$B$27 | CG6: 현물결제일 S0 | CH6: =설정!$B$27
A7: 최종결제일 H | B7: =설정!$B$21 | AQ7: 최종결제일 H | AR7: =설정!$B$21 | CG7: 최종결제일 H | CH7: =설정!$B$21
A8: 현물 수익률(소수) | B8: =바스켓!C17 | AQ8: 현물 수익률(소수) | AR8: =바스켓!D17 | CG8: 현물 수익률(소수) | CH8: =바스켓!E17
A9: 조달금리(소수) | B9: =설정!$B$32 | AQ9: 조달금리(소수) | AR9: =설정!$B$32 | CG9: 조달금리(소수) | CH9: =설정!$B$32
A10: 재투자금리(소수) | B10: =설정!$B$34 | AQ10: 재투자금리(소수) | AR10: =설정!$B$34 | CG10: 재투자금리(소수) | CH10: =설정!$B$34
A11: 이자일수기준 | B11: =설정!$B$35 | AQ11: 이자일수기준 | AR11: =설정!$B$35 | CG11: 이자일수기준 | CH11: =설정!$B$35
A12: ■ 종목1 이표 스케줄 | AQ12: ■ 종목2 이표 스케줄 | CG12: ■ 종목3 이표 스케줄
A14: k | B14: 이표일 | C14: CF(100기준) | D14: 현물포함 | E14: 현물idx | F14: PV@y | G14: PV@y+1bp | H14: PV@y-1bp | I14: 선도포함 | J14: 선도idx | K14: PV_H@y0 | L14: PV_H@y0+ | M14: PV_H@y0- | N14: PV_H@y1 | O14: PV_H@y2 | P14: PV_H@y2+ | Q14: PV_H@y2- | R14: 쿠폰재투자FV | S14: PV_H@손익shift | T14: PV_H@시나리오1 | U14: PV_H@시나리오2 | V14: PV_H@시나리오3 | W14: PV_H@시나리오4 | X14: PV_H@시나리오5 | Y14: PV_H@시나리오6 | Z14: PV_H@시나리오7 | AA14: PV_H@시나리오8 | AB14: PV_H@시나리오9 | AC14: PV_H@시나리오10 | AD14: PV_H@시나리오11 | AE14: PV_H@시나리오12 | AF14: PV_H@시나리오13 | AG14: PV_H@시나리오14 | AH14: PV_H@시나리오15 | AI14: PV_H@시나리오16 | AJ14: PV_H@시나리오17 | AK14: PV_H@시나리오18 | AL14: PV_H@시나리오19 | AM14: PV_H@시나리오20 | AN14: PV_H@시나리오21 | AQ14: k | AR14: 이표일 | AS14: CF(100기준) | AT14: 현물포함 | AU14: 현물idx | AV14: PV@y | AW14: PV@y+1bp | AX14: PV@y-1bp | AY14: 선도포함 | AZ14: 선도idx | BA14: PV_H@y0 | BB14: PV_H@y0+ | BC14: PV_H@y0- | BD14: PV_H@y1 | BE14: PV_H@y2 | BF14: PV_H@y2+ | BG14: PV_H@y2- | BH14: 쿠폰재투자FV | BI14: PV_H@손익shift | BJ14: PV_H@시나리오1 | BK14: PV_H@시나리오2 | BL14: PV_H@시나리오3 | BM14: PV_H@시나리오4 | BN14: PV_H@시나리오5 | BO14: PV_H@시나리오6 | BP14: PV_H@시나리오7 | BQ14: PV_H@시나리오8 | BR14: PV_H@시나리오9 | BS14: PV_H@시나리오10 | BT14: PV_H@시나리오11 | BU14: PV_H@시나리오12 | BV14: PV_H@시나리오13 | BW14: PV_H@시나리오14 | BX14: PV_H@시나리오15 | BY14: PV_H@시나리오16 | BZ14: PV_H@시나리오17 | CA14: PV_H@시나리오18 | CB14: PV_H@시나리오19 | CC14: PV_H@시나리오20 | CD14: PV_H@시나리오21 | CG14: k | CH14: 이표일 | CI14: CF(100기준) | CJ14: 현물포함 | CK14: 현물idx | CL14: PV@y | CM14: PV@y+1bp | CN14: PV@y-1bp | CO14: 선도포함 | CP14: 선도idx | CQ14: PV_H@y0 | CR14: PV_H@y0+ | CS14: PV_H@y0- | CT14: PV_H@y1 | CU14: PV_H@y2 | CV14: PV_H@y2+ | CW14: PV_H@y2- | CX14: 쿠폰재투자FV | CY14: PV_H@손익shift | CZ14: PV_H@시나리오1 | DA14: PV_H@시나리오2 | DB14: PV_H@시나리오3 | DC14: PV_H@시나리오4 | DD14: PV_H@시나리오5 | DE14: PV_H@시나리오6 | DF14: PV_H@시나리오7 | DG14: PV_H@시나리오8 | DH14: PV_H@시나리오9 | DI14: PV_H@시나리오10 | DJ14: PV_H@시나리오11 | DK14: PV_H@시나리오12 | DL14: PV_H@시나리오13 | DM14: PV_H@시나리오14 | DN14: PV_H@시나리오15 | DO14: PV_H@시나리오16 | DP14: PV_H@시나리오17 | DQ14: PV_H@시나리오18 | DR14: PV_H@시나리오19 | DS14: PV_H@시나리오20 | DT14: PV_H@시나리오21
A15: 1 | B15: =EDATE($B$2,-6*(62-$A15)) | C15: =IF(AND(B15>$B$3,B15<=$B$2),IF(B15=$B$2,$B$5+100,$B$5),0) | D15: =IF(AND($C15>0,B15>$B$6),1,0) | E15: =IF(D15=1,SUM($D$15:D15),"") | F15: =IF(D15=1,$C15/(1+$B$8/2)^(E15-1),0) | G15: =IF(D15=1,$C15/(1+($B$8+0.0001)/2)^(E15-1),0) | H15: =IF(D15=1,$C15/(1+($B$8-0.0001)/2)^(E15-1),0) | I15: =IF(AND($C15>0,B15>$B$7),1,0) | J15: =IF(I15=1,SUM($I$15:I15),"") | K15: =IF(I15=1,$C15/(1+$B$104/2)^(J15-1),0) | L15: =IF(I15=1,$C15/(1+($B$104+0.0001)/2)^(J15-1),0) | M15: =IF(I15=1,$C15/(1+($B$104-0.0001)/2)^(J15-1),0) | N15: =IF(I15=1,$C15/(1+$B$109/2)^(J15-1),0) | O15: =IF(I15=1,$C15/(1+$B$111/2)^(J15-1),0) | P15: =IF(I15=1,$C15/(1+($B$111+0.0001)/2)^(J15-1),0) | Q15: =IF(I15=1,$C15/(1+($B$111-0.0001)/2)^(J15-1),0) | R15: =IF(AND($C15>0,B15>$B$6,B15<=$B$7),$C15*(1+$B$10*($B$7-B15)/365),0) | S15: =IF(I15=1,$C15/(1+($B$111+손익!$B$24/10000)/2)^(J15-1),0) | T15: =IF(I15=1,$C15/(1+($B$111+시나리오!$A$4/10000)/2)^(J15-1),0) | U15: =IF(I15=1,$C15/(1+($B$111+시나리오!$A$5/10000)/2)^(J15-1),0) | V15: =IF(I15=1,$C15/(1+($B$111+시나리오!$A$6/10000)/2)^(J15-1),0) | W15: =IF(I15=1,$C15/(1+($B$111+시나리오!$A$7/10000)/2)^(J15-1),0) | X15: =IF(I15=1,$C15/(1+($B$111+시나리오!$A$8/10000)/2)^(J15-1),0) | Y15: =IF(I15=1,$C15/(1+($B$111+시나리오!$A$9/10000)/2)^(J15-1),0) | Z15: =IF(I15=1,$C15/(1+($B$111+시나리오!$A$10/10000)/2)^(J15-1),0) | AA15: =IF(I15=1,$C15/(1+($B$111+시나리오!$A$11/10000)/2)^(J15-1),0) | AB15: =IF(I15=1,$C15/(1+($B$111+시나리오!$A$12/10000)/2)^(J15-1),0) | AC15: =IF(I15=1,$C15/(1+($B$111+시나리오!$A$13/10000)/2)^(J15-1),0) | AD15: =IF(I15=1,$C15/(1+($B$111+시나리오!$A$14/10000)/2)^(J15-1),0) | AE15: =IF(I15=1,$C15/(1+($B$111+시나리오!$A$15/10000)/2)^(J15-1),0) | AF15: =IF(I15=1,$C15/(1+($B$111+시나리오!$A$16/10000)/2)^(J15-1),0) | AG15: =IF(I15=1,$C15/(1+($B$111+시나리오!$A$17/10000)/2)^(J15-1),0) | AH15: =IF(I15=1,$C15/(1+($B$111+시나리오!$A$18/10000)/2)^(J15-1),0) | AI15: =IF(I15=1,$C15/(1+($B$111+시나리오!$A$19/10000)/2)^(J15-1),0) | AJ15: =IF(I15=1,$C15/(1+($B$111+시나리오!$A$20/10000)/2)^(J15-1),0) | AK15: =IF(I15=1,$C15/(1+($B$111+시나리오!$A$21/10000)/2)^(J15-1),0) | AL15: =IF(I15=1,$C15/(1+($B$111+시나리오!$A$22/10000)/2)^(J15-1),0) | AM15: =IF(I15=1,$C15/(1+($B$111+시나리오!$A$23/10000)/2)^(J15-1),0) | AN15: =IF(I15=1,$C15/(1+($B$111+시나리오!$A$24/10000)/2)^(J15-1),0) | AQ15: 1 | AR15: =EDATE($AR$2,-6*(62-$AQ15)) | AS15: =IF(AND(AR15>$AR$3,AR15<=$AR$2),IF(AR15=$AR$2,$AR$5+100,$AR$5),0) | AT15: =IF(AND($AS15>0,AR15>$AR$6),1,0) | AU15: =IF(AT15=1,SUM($AT$15:AT15),"") | AV15: =IF(AT15=1,$AS15/(1+$AR$8/2)^(AU15-1),0) | AW15: =IF(AT15=1,$AS15/(1+($AR$8+0.0001)/2)^(AU15-1),0) | AX15: =IF(AT15=1,$AS15/(1+($AR$8-0.0001)/2)^(AU15-1),0) | AY15: =IF(AND($AS15>0,AR15>$AR$7),1,0) | AZ15: =IF(AY15=1,SUM($AY$15:AY15),"") | BA15: =IF(AY15=1,$AS15/(1+$AR$104/2)^(AZ15-1),0) | BB15: =IF(AY15=1,$AS15/(1+($AR$104+0.0001)/2)^(AZ15-1),0) | BC15: =IF(AY15=1,$AS15/(1+($AR$104-0.0001)/2)^(AZ15-1),0) | BD15: =IF(AY15=1,$AS15/(1+$AR$109/2)^(AZ15-1),0) | BE15: =IF(AY15=1,$AS15/(1+$AR$111/2)^(AZ15-1),0) | BF15: =IF(AY15=1,$AS15/(1+($AR$111+0.0001)/2)^(AZ15-1),0) | BG15: =IF(AY15=1,$AS15/(1+($AR$111-0.0001)/2)^(AZ15-1),0) | BH15: =IF(AND($AS15>0,AR15>$AR$6,AR15<=$AR$7),$AS15*(1+$AR$10*($AR$7-AR15)/365),0) | BI15: =IF(AY15=1,$AS15/(1+($AR$111+손익!$B$24/10000)/2)^(AZ15-1),0) | BJ15: =IF(AY15=1,$AS15/(1+($AR$111+시나리오!$A$4/10000)/2)^(AZ15-1),0) | BK15: =IF(AY15=1,$AS15/(1+($AR$111+시나리오!$A$5/10000)/2)^(AZ15-1),0) | BL15: =IF(AY15=1,$AS15/(1+($AR$111+시나리오!$A$6/10000)/2)^(AZ15-1),0) | BM15: =IF(AY15=1,$AS15/(1+($AR$111+시나리오!$A$7/10000)/2)^(AZ15-1),0) | BN15: =IF(AY15=1,$AS15/(1+($AR$111+시나리오!$A$8/10000)/2)^(AZ15-1),0) | BO15: =IF(AY15=1,$AS15/(1+($AR$111+시나리오!$A$9/10000)/2)^(AZ15-1),0) | BP15: =IF(AY15=1,$AS15/(1+($AR$111+시나리오!$A$10/10000)/2)^(AZ15-1),0) | BQ15: =IF(AY15=1,$AS15/(1+($AR$111+시나리오!$A$11/10000)/2)^(AZ15-1),0) | BR15: =IF(AY15=1,$AS15/(1+($AR$111+시나리오!$A$12/10000)/2)^(AZ15-1),0) | BS15: =IF(AY15=1,$AS15/(1+($AR$111+시나리오!$A$13/10000)/2)^(AZ15-1),0) | BT15: =IF(AY15=1,$AS15/(1+($AR$111+시나리오!$A$14/10000)/2)^(AZ15-1),0) | BU15: =IF(AY15=1,$AS15/(1+($AR$111+시나리오!$A$15/10000)/2)^(AZ15-1),0) | BV15: =IF(AY15=1,$AS15/(1+($AR$111+시나리오!$A$16/10000)/2)^(AZ15-1),0) | BW15: =IF(AY15=1,$AS15/(1+($AR$111+시나리오!$A$17/10000)/2)^(AZ15-1),0) | BX15: =IF(AY15=1,$AS15/(1+($AR$111+시나리오!$A$18/10000)/2)^(AZ15-1),0) | BY15: =IF(AY15=1,$AS15/(1+($AR$111+시나리오!$A$19/10000)/2)^(AZ15-1),0) | BZ15: =IF(AY15=1,$AS15/(1+($AR$111+시나리오!$A$20/10000)/2)^(AZ15-1),0) | CA15: =IF(AY15=1,$AS15/(1+($AR$111+시나리오!$A$21/10000)/2)^(AZ15-1),0) | CB15: =IF(AY15=1,$AS15/(1+($AR$111+시나리오!$A$22/10000)/2)^(AZ15-1),0) | CC15: =IF(AY15=1,$AS15/(1+($AR$111+시나리오!$A$23/10000)/2)^(AZ15-1),0) | CD15: =IF(AY15=1,$AS15/(1+($AR$111+시나리오!$A$24/10000)/2)^(AZ15-1),0) | CG15: 1 | CH15: =EDATE($CH$2,-6*(62-$CG15)) | CI15: =IF(AND(CH15>$CH$3,CH15<=$CH$2),IF(CH15=$CH$2,$CH$5+100,$CH$5),0) | CJ15: =IF(AND($CI15>0,CH15>$CH$6),1,0) | CK15: =IF(CJ15=1,SUM($CJ$15:CJ15),"") | CL15: =IF(CJ15=1,$CI15/(1+$CH$8/2)^(CK15-1),0) | CM15: =IF(CJ15=1,$CI15/(1+($CH$8+0.0001)/2)^(CK15-1),0) | CN15: =IF(CJ15=1,$CI15/(1+($CH$8-0.0001)/2)^(CK15-1),0) | CO15: =IF(AND($CI15>0,CH15>$CH$7),1,0) | CP15: =IF(CO15=1,SUM($CO$15:CO15),"") | CQ15: =IF(CO15=1,$CI15/(1+$CH$104/2)^(CP15-1),0) | CR15: =IF(CO15=1,$CI15/(1+($CH$104+0.0001)/2)^(CP15-1),0) | CS15: =IF(CO15=1,$CI15/(1+($CH$104-0.0001)/2)^(CP15-1),0) | CT15: =IF(CO15=1,$CI15/(1+$CH$109/2)^(CP15-1),0) | CU15: =IF(CO15=1,$CI15/(1+$CH$111/2)^(CP15-1),0) | CV15: =IF(CO15=1,$CI15/(1+($CH$111+0.0001)/2)^(CP15-1),0) | CW15: =IF(CO15=1,$CI15/(1+($CH$111-0.0001)/2)^(CP15-1),0) | CX15: =IF(AND($CI15>0,CH15>$CH$6,CH15<=$CH$7),$CI15*(1+$CH$10*($CH$7-CH15)/365),0) | CY15: =IF(CO15=1,$CI15/(1+($CH$111+손익!$B$24/10000)/2)^(CP15-1),0) | CZ15: =IF(CO15=1,$CI15/(1+($CH$111+시나리오!$A$4/10000)/2)^(CP15-1),0) | DA15: =IF(CO15=1,$CI15/(1+($CH$111+시나리오!$A$5/10000)/2)^(CP15-1),0) | DB15: =IF(CO15=1,$CI15/(1+($CH$111+시나리오!$A$6/10000)/2)^(CP15-1),0) | DC15: =IF(CO15=1,$CI15/(1+($CH$111+시나리오!$A$7/10000)/2)^(CP15-1),0) | DD15: =IF(CO15=1,$CI15/(1+($CH$111+시나리오!$A$8/10000)/2)^(CP15-1),0) | DE15: =IF(CO15=1,$CI15/(1+($CH$111+시나리오!$A$9/10000)/2)^(CP15-1),0) | DF15: =IF(CO15=1,$CI15/(1+($CH$111+시나리오!$A$10/10000)/2)^(CP15-1),0) | DG15: =IF(CO15=1,$CI15/(1+($CH$111+시나리오!$A$11/10000)/2)^(CP15-1),0) | DH15: =IF(CO15=1,$CI15/(1+($CH$111+시나리오!$A$12/10000)/2)^(CP15-1),0) | DI15: =IF(CO15=1,$CI15/(1+($CH$111+시나리오!$A$13/10000)/2)^(CP15-1),0) | DJ15: =IF(CO15=1,$CI15/(1+($CH$111+시나리오!$A$14/10000)/2)^(CP15-1),0) | DK15: =IF(CO15=1,$CI15/(1+($CH$111+시나리오!$A$15/10000)/2)^(CP15-1),0) | DL15: =IF(CO15=1,$CI15/(1+($CH$111+시나리오!$A$16/10000)/2)^(CP15-1),0) | DM15: =IF(CO15=1,$CI15/(1+($CH$111+시나리오!$A$17/10000)/2)^(CP15-1),0) | DN15: =IF(CO15=1,$CI15/(1+($CH$111+시나리오!$A$18/10000)/2)^(CP15-1),0) | DO15: =IF(CO15=1,$CI15/(1+($CH$111+시나리오!$A$19/10000)/2)^(CP15-1),0) | DP15: =IF(CO15=1,$CI15/(1+($CH$111+시나리오!$A$20/10000)/2)^(CP15-1),0) | DQ15: =IF(CO15=1,$CI15/(1+($CH$111+시나리오!$A$21/10000)/2)^(CP15-1),0) | DR15: =IF(CO15=1,$CI15/(1+($CH$111+시나리오!$A$22/10000)/2)^(CP15-1),0) | DS15: =IF(CO15=1,$CI15/(1+($CH$111+시나리오!$A$23/10000)/2)^(CP15-1),0) | DT15: =IF(CO15=1,$CI15/(1+($CH$111+시나리오!$A$24/10000)/2)^(CP15-1),0)
A16: 2 | B16: =EDATE($B$2,-6*(62-$A16)) | C16: =IF(AND(B16>$B$3,B16<=$B$2),IF(B16=$B$2,$B$5+100,$B$5),0) | D16: =IF(AND($C16>0,B16>$B$6),1,0) | E16: =IF(D16=1,SUM($D$15:D16),"") | F16: =IF(D16=1,$C16/(1+$B$8/2)^(E16-1),0) | G16: =IF(D16=1,$C16/(1+($B$8+0.0001)/2)^(E16-1),0) | H16: =IF(D16=1,$C16/(1+($B$8-0.0001)/2)^(E16-1),0) | I16: =IF(AND($C16>0,B16>$B$7),1,0) | J16: =IF(I16=1,SUM($I$15:I16),"") | K16: =IF(I16=1,$C16/(1+$B$104/2)^(J16-1),0) | L16: =IF(I16=1,$C16/(1+($B$104+0.0001)/2)^(J16-1),0) | M16: =IF(I16=1,$C16/(1+($B$104-0.0001)/2)^(J16-1),0) | N16: =IF(I16=1,$C16/(1+$B$109/2)^(J16-1),0) | O16: =IF(I16=1,$C16/(1+$B$111/2)^(J16-1),0) | P16: =IF(I16=1,$C16/(1+($B$111+0.0001)/2)^(J16-1),0) | Q16: =IF(I16=1,$C16/(1+($B$111-0.0001)/2)^(J16-1),0) | R16: =IF(AND($C16>0,B16>$B$6,B16<=$B$7),$C16*(1+$B$10*($B$7-B16)/365),0) | S16: =IF(I16=1,$C16/(1+($B$111+손익!$B$24/10000)/2)^(J16-1),0) | T16: =IF(I16=1,$C16/(1+($B$111+시나리오!$A$4/10000)/2)^(J16-1),0) | U16: =IF(I16=1,$C16/(1+($B$111+시나리오!$A$5/10000)/2)^(J16-1),0) | V16: =IF(I16=1,$C16/(1+($B$111+시나리오!$A$6/10000)/2)^(J16-1),0) | W16: =IF(I16=1,$C16/(1+($B$111+시나리오!$A$7/10000)/2)^(J16-1),0) | X16: =IF(I16=1,$C16/(1+($B$111+시나리오!$A$8/10000)/2)^(J16-1),0) | Y16: =IF(I16=1,$C16/(1+($B$111+시나리오!$A$9/10000)/2)^(J16-1),0) | Z16: =IF(I16=1,$C16/(1+($B$111+시나리오!$A$10/10000)/2)^(J16-1),0) | AA16: =IF(I16=1,$C16/(1+($B$111+시나리오!$A$11/10000)/2)^(J16-1),0) | AB16: =IF(I16=1,$C16/(1+($B$111+시나리오!$A$12/10000)/2)^(J16-1),0) | AC16: =IF(I16=1,$C16/(1+($B$111+시나리오!$A$13/10000)/2)^(J16-1),0) | AD16: =IF(I16=1,$C16/(1+($B$111+시나리오!$A$14/10000)/2)^(J16-1),0) | AE16: =IF(I16=1,$C16/(1+($B$111+시나리오!$A$15/10000)/2)^(J16-1),0) | AF16: =IF(I16=1,$C16/(1+($B$111+시나리오!$A$16/10000)/2)^(J16-1),0) | AG16: =IF(I16=1,$C16/(1+($B$111+시나리오!$A$17/10000)/2)^(J16-1),0) | AH16: =IF(I16=1,$C16/(1+($B$111+시나리오!$A$18/10000)/2)^(J16-1),0) | AI16: =IF(I16=1,$C16/(1+($B$111+시나리오!$A$19/10000)/2)^(J16-1),0) | AJ16: =IF(I16=1,$C16/(1+($B$111+시나리오!$A$20/10000)/2)^(J16-1),0) | AK16: =IF(I16=1,$C16/(1+($B$111+시나리오!$A$21/10000)/2)^(J16-1),0) | AL16: =IF(I16=1,$C16/(1+($B$111+시나리오!$A$22/10000)/2)^(J16-1),0) | AM16: =IF(I16=1,$C16/(1+($B$111+시나리오!$A$23/10000)/2)^(J16-1),0) | AN16: =IF(I16=1,$C16/(1+($B$111+시나리오!$A$24/10000)/2)^(J16-1),0) | AQ16: 2 | AR16: =EDATE($AR$2,-6*(62-$AQ16)) | AS16: =IF(AND(AR16>$AR$3,AR16<=$AR$2),IF(AR16=$AR$2,$AR$5+100,$AR$5),0) | AT16: =IF(AND($AS16>0,AR16>$AR$6),1,0) | AU16: =IF(AT16=1,SUM($AT$15:AT16),"") | AV16: =IF(AT16=1,$AS16/(1+$AR$8/2)^(AU16-1),0) | AW16: =IF(AT16=1,$AS16/(1+($AR$8+0.0001)/2)^(AU16-1),0) | AX16: =IF(AT16=1,$AS16/(1+($AR$8-0.0001)/2)^(AU16-1),0) | AY16: =IF(AND($AS16>0,AR16>$AR$7),1,0) | AZ16: =IF(AY16=1,SUM($AY$15:AY16),"") | BA16: =IF(AY16=1,$AS16/(1+$AR$104/2)^(AZ16-1),0) | BB16: =IF(AY16=1,$AS16/(1+($AR$104+0.0001)/2)^(AZ16-1),0) | BC16: =IF(AY16=1,$AS16/(1+($AR$104-0.0001)/2)^(AZ16-1),0) | BD16: =IF(AY16=1,$AS16/(1+$AR$109/2)^(AZ16-1),0) | BE16: =IF(AY16=1,$AS16/(1+$AR$111/2)^(AZ16-1),0) | BF16: =IF(AY16=1,$AS16/(1+($AR$111+0.0001)/2)^(AZ16-1),0) | BG16: =IF(AY16=1,$AS16/(1+($AR$111-0.0001)/2)^(AZ16-1),0) | BH16: =IF(AND($AS16>0,AR16>$AR$6,AR16<=$AR$7),$AS16*(1+$AR$10*($AR$7-AR16)/365),0) | BI16: =IF(AY16=1,$AS16/(1+($AR$111+손익!$B$24/10000)/2)^(AZ16-1),0) | BJ16: =IF(AY16=1,$AS16/(1+($AR$111+시나리오!$A$4/10000)/2)^(AZ16-1),0) | BK16: =IF(AY16=1,$AS16/(1+($AR$111+시나리오!$A$5/10000)/2)^(AZ16-1),0) | BL16: =IF(AY16=1,$AS16/(1+($AR$111+시나리오!$A$6/10000)/2)^(AZ16-1),0) | BM16: =IF(AY16=1,$AS16/(1+($AR$111+시나리오!$A$7/10000)/2)^(AZ16-1),0) | BN16: =IF(AY16=1,$AS16/(1+($AR$111+시나리오!$A$8/10000)/2)^(AZ16-1),0) | BO16: =IF(AY16=1,$AS16/(1+($AR$111+시나리오!$A$9/10000)/2)^(AZ16-1),0) | BP16: =IF(AY16=1,$AS16/(1+($AR$111+시나리오!$A$10/10000)/2)^(AZ16-1),0) | BQ16: =IF(AY16=1,$AS16/(1+($AR$111+시나리오!$A$11/10000)/2)^(AZ16-1),0) | BR16: =IF(AY16=1,$AS16/(1+($AR$111+시나리오!$A$12/10000)/2)^(AZ16-1),0) | BS16: =IF(AY16=1,$AS16/(1+($AR$111+시나리오!$A$13/10000)/2)^(AZ16-1),0) | BT16: =IF(AY16=1,$AS16/(1+($AR$111+시나리오!$A$14/10000)/2)^(AZ16-1),0) | BU16: =IF(AY16=1,$AS16/(1+($AR$111+시나리오!$A$15/10000)/2)^(AZ16-1),0) | BV16: =IF(AY16=1,$AS16/(1+($AR$111+시나리오!$A$16/10000)/2)^(AZ16-1),0) | BW16: =IF(AY16=1,$AS16/(1+($AR$111+시나리오!$A$17/10000)/2)^(AZ16-1),0) | BX16: =IF(AY16=1,$AS16/(1+($AR$111+시나리오!$A$18/10000)/2)^(AZ16-1),0) | BY16: =IF(AY16=1,$AS16/(1+($AR$111+시나리오!$A$19/10000)/2)^(AZ16-1),0) | BZ16: =IF(AY16=1,$AS16/(1+($AR$111+시나리오!$A$20/10000)/2)^(AZ16-1),0) | CA16: =IF(AY16=1,$AS16/(1+($AR$111+시나리오!$A$21/10000)/2)^(AZ16-1),0) | CB16: =IF(AY16=1,$AS16/(1+($AR$111+시나리오!$A$22/10000)/2)^(AZ16-1),0) | CC16: =IF(AY16=1,$AS16/(1+($AR$111+시나리오!$A$23/10000)/2)^(AZ16-1),0) | CD16: =IF(AY16=1,$AS16/(1+($AR$111+시나리오!$A$24/10000)/2)^(AZ16-1),0) | CG16: 2 | CH16: =EDATE($CH$2,-6*(62-$CG16)) | CI16: =IF(AND(CH16>$CH$3,CH16<=$CH$2),IF(CH16=$CH$2,$CH$5+100,$CH$5),0) | CJ16: =IF(AND($CI16>0,CH16>$CH$6),1,0) | CK16: =IF(CJ16=1,SUM($CJ$15:CJ16),"") | CL16: =IF(CJ16=1,$CI16/(1+$CH$8/2)^(CK16-1),0) | CM16: =IF(CJ16=1,$CI16/(1+($CH$8+0.0001)/2)^(CK16-1),0) | CN16: =IF(CJ16=1,$CI16/(1+($CH$8-0.0001)/2)^(CK16-1),0) | CO16: =IF(AND($CI16>0,CH16>$CH$7),1,0) | CP16: =IF(CO16=1,SUM($CO$15:CO16),"") | CQ16: =IF(CO16=1,$CI16/(1+$CH$104/2)^(CP16-1),0) | CR16: =IF(CO16=1,$CI16/(1+($CH$104+0.0001)/2)^(CP16-1),0) | CS16: =IF(CO16=1,$CI16/(1+($CH$104-0.0001)/2)^(CP16-1),0) | CT16: =IF(CO16=1,$CI16/(1+$CH$109/2)^(CP16-1),0) | CU16: =IF(CO16=1,$CI16/(1+$CH$111/2)^(CP16-1),0) | CV16: =IF(CO16=1,$CI16/(1+($CH$111+0.0001)/2)^(CP16-1),0) | CW16: =IF(CO16=1,$CI16/(1+($CH$111-0.0001)/2)^(CP16-1),0) | CX16: =IF(AND($CI16>0,CH16>$CH$6,CH16<=$CH$7),$CI16*(1+$CH$10*($CH$7-CH16)/365),0) | CY16: =IF(CO16=1,$CI16/(1+($CH$111+손익!$B$24/10000)/2)^(CP16-1),0) | CZ16: =IF(CO16=1,$CI16/(1+($CH$111+시나리오!$A$4/10000)/2)^(CP16-1),0) | DA16: =IF(CO16=1,$CI16/(1+($CH$111+시나리오!$A$5/10000)/2)^(CP16-1),0) | DB16: =IF(CO16=1,$CI16/(1+($CH$111+시나리오!$A$6/10000)/2)^(CP16-1),0) | DC16: =IF(CO16=1,$CI16/(1+($CH$111+시나리오!$A$7/10000)/2)^(CP16-1),0) | DD16: =IF(CO16=1,$CI16/(1+($CH$111+시나리오!$A$8/10000)/2)^(CP16-1),0) | DE16: =IF(CO16=1,$CI16/(1+($CH$111+시나리오!$A$9/10000)/2)^(CP16-1),0) | DF16: =IF(CO16=1,$CI16/(1+($CH$111+시나리오!$A$10/10000)/2)^(CP16-1),0) | DG16: =IF(CO16=1,$CI16/(1+($CH$111+시나리오!$A$11/10000)/2)^(CP16-1),0) | DH16: =IF(CO16=1,$CI16/(1+($CH$111+시나리오!$A$12/10000)/2)^(CP16-1),0) | DI16: =IF(CO16=1,$CI16/(1+($CH$111+시나리오!$A$13/10000)/2)^(CP16-1),0) | DJ16: =IF(CO16=1,$CI16/(1+($CH$111+시나리오!$A$14/10000)/2)^(CP16-1),0) | DK16: =IF(CO16=1,$CI16/(1+($CH$111+시나리오!$A$15/10000)/2)^(CP16-1),0) | DL16: =IF(CO16=1,$CI16/(1+($CH$111+시나리오!$A$16/10000)/2)^(CP16-1),0) | DM16: =IF(CO16=1,$CI16/(1+($CH$111+시나리오!$A$17/10000)/2)^(CP16-1),0) | DN16: =IF(CO16=1,$CI16/(1+($CH$111+시나리오!$A$18/10000)/2)^(CP16-1),0) | DO16: =IF(CO16=1,$CI16/(1+($CH$111+시나리오!$A$19/10000)/2)^(CP16-1),0) | DP16: =IF(CO16=1,$CI16/(1+($CH$111+시나리오!$A$20/10000)/2)^(CP16-1),0) | DQ16: =IF(CO16=1,$CI16/(1+($CH$111+시나리오!$A$21/10000)/2)^(CP16-1),0) | DR16: =IF(CO16=1,$CI16/(1+($CH$111+시나리오!$A$22/10000)/2)^(CP16-1),0) | DS16: =IF(CO16=1,$CI16/(1+($CH$111+시나리오!$A$23/10000)/2)^(CP16-1),0) | DT16: =IF(CO16=1,$CI16/(1+($CH$111+시나리오!$A$24/10000)/2)^(CP16-1),0)
A17: 3 | B17: =EDATE($B$2,-6*(62-$A17)) | C17: =IF(AND(B17>$B$3,B17<=$B$2),IF(B17=$B$2,$B$5+100,$B$5),0) | D17: =IF(AND($C17>0,B17>$B$6),1,0) | E17: =IF(D17=1,SUM($D$15:D17),"") | F17: =IF(D17=1,$C17/(1+$B$8/2)^(E17-1),0) | G17: =IF(D17=1,$C17/(1+($B$8+0.0001)/2)^(E17-1),0) | H17: =IF(D17=1,$C17/(1+($B$8-0.0001)/2)^(E17-1),0) | I17: =IF(AND($C17>0,B17>$B$7),1,0) | J17: =IF(I17=1,SUM($I$15:I17),"") | K17: =IF(I17=1,$C17/(1+$B$104/2)^(J17-1),0) | L17: =IF(I17=1,$C17/(1+($B$104+0.0001)/2)^(J17-1),0) | M17: =IF(I17=1,$C17/(1+($B$104-0.0001)/2)^(J17-1),0) | N17: =IF(I17=1,$C17/(1+$B$109/2)^(J17-1),0) | O17: =IF(I17=1,$C17/(1+$B$111/2)^(J17-1),0) | P17: =IF(I17=1,$C17/(1+($B$111+0.0001)/2)^(J17-1),0) | Q17: =IF(I17=1,$C17/(1+($B$111-0.0001)/2)^(J17-1),0) | R17: =IF(AND($C17>0,B17>$B$6,B17<=$B$7),$C17*(1+$B$10*($B$7-B17)/365),0) | S17: =IF(I17=1,$C17/(1+($B$111+손익!$B$24/10000)/2)^(J17-1),0) | T17: =IF(I17=1,$C17/(1+($B$111+시나리오!$A$4/10000)/2)^(J17-1),0) | U17: =IF(I17=1,$C17/(1+($B$111+시나리오!$A$5/10000)/2)^(J17-1),0) | V17: =IF(I17=1,$C17/(1+($B$111+시나리오!$A$6/10000)/2)^(J17-1),0) | W17: =IF(I17=1,$C17/(1+($B$111+시나리오!$A$7/10000)/2)^(J17-1),0) | X17: =IF(I17=1,$C17/(1+($B$111+시나리오!$A$8/10000)/2)^(J17-1),0) | Y17: =IF(I17=1,$C17/(1+($B$111+시나리오!$A$9/10000)/2)^(J17-1),0) | Z17: =IF(I17=1,$C17/(1+($B$111+시나리오!$A$10/10000)/2)^(J17-1),0) | AA17: =IF(I17=1,$C17/(1+($B$111+시나리오!$A$11/10000)/2)^(J17-1),0) | AB17: =IF(I17=1,$C17/(1+($B$111+시나리오!$A$12/10000)/2)^(J17-1),0) | AC17: =IF(I17=1,$C17/(1+($B$111+시나리오!$A$13/10000)/2)^(J17-1),0) | AD17: =IF(I17=1,$C17/(1+($B$111+시나리오!$A$14/10000)/2)^(J17-1),0) | AE17: =IF(I17=1,$C17/(1+($B$111+시나리오!$A$15/10000)/2)^(J17-1),0) | AF17: =IF(I17=1,$C17/(1+($B$111+시나리오!$A$16/10000)/2)^(J17-1),0) | AG17: =IF(I17=1,$C17/(1+($B$111+시나리오!$A$17/10000)/2)^(J17-1),0) | AH17: =IF(I17=1,$C17/(1+($B$111+시나리오!$A$18/10000)/2)^(J17-1),0) | AI17: =IF(I17=1,$C17/(1+($B$111+시나리오!$A$19/10000)/2)^(J17-1),0) | AJ17: =IF(I17=1,$C17/(1+($B$111+시나리오!$A$20/10000)/2)^(J17-1),0) | AK17: =IF(I17=1,$C17/(1+($B$111+시나리오!$A$21/10000)/2)^(J17-1),0) | AL17: =IF(I17=1,$C17/(1+($B$111+시나리오!$A$22/10000)/2)^(J17-1),0) | AM17: =IF(I17=1,$C17/(1+($B$111+시나리오!$A$23/10000)/2)^(J17-1),0) | AN17: =IF(I17=1,$C17/(1+($B$111+시나리오!$A$24/10000)/2)^(J17-1),0) | AQ17: 3 | AR17: =EDATE($AR$2,-6*(62-$AQ17)) | AS17: =IF(AND(AR17>$AR$3,AR17<=$AR$2),IF(AR17=$AR$2,$AR$5+100,$AR$5),0) | AT17: =IF(AND($AS17>0,AR17>$AR$6),1,0) | AU17: =IF(AT17=1,SUM($AT$15:AT17),"") | AV17: =IF(AT17=1,$AS17/(1+$AR$8/2)^(AU17-1),0) | AW17: =IF(AT17=1,$AS17/(1+($AR$8+0.0001)/2)^(AU17-1),0) | AX17: =IF(AT17=1,$AS17/(1+($AR$8-0.0001)/2)^(AU17-1),0) | AY17: =IF(AND($AS17>0,AR17>$AR$7),1,0) | AZ17: =IF(AY17=1,SUM($AY$15:AY17),"") | BA17: =IF(AY17=1,$AS17/(1+$AR$104/2)^(AZ17-1),0) | BB17: =IF(AY17=1,$AS17/(1+($AR$104+0.0001)/2)^(AZ17-1),0) | BC17: =IF(AY17=1,$AS17/(1+($AR$104-0.0001)/2)^(AZ17-1),0) | BD17: =IF(AY17=1,$AS17/(1+$AR$109/2)^(AZ17-1),0) | BE17: =IF(AY17=1,$AS17/(1+$AR$111/2)^(AZ17-1),0) | BF17: =IF(AY17=1,$AS17/(1+($AR$111+0.0001)/2)^(AZ17-1),0) | BG17: =IF(AY17=1,$AS17/(1+($AR$111-0.0001)/2)^(AZ17-1),0) | BH17: =IF(AND($AS17>0,AR17>$AR$6,AR17<=$AR$7),$AS17*(1+$AR$10*($AR$7-AR17)/365),0) | BI17: =IF(AY17=1,$AS17/(1+($AR$111+손익!$B$24/10000)/2)^(AZ17-1),0) | BJ17: =IF(AY17=1,$AS17/(1+($AR$111+시나리오!$A$4/10000)/2)^(AZ17-1),0) | BK17: =IF(AY17=1,$AS17/(1+($AR$111+시나리오!$A$5/10000)/2)^(AZ17-1),0) | BL17: =IF(AY17=1,$AS17/(1+($AR$111+시나리오!$A$6/10000)/2)^(AZ17-1),0) | BM17: =IF(AY17=1,$AS17/(1+($AR$111+시나리오!$A$7/10000)/2)^(AZ17-1),0) | BN17: =IF(AY17=1,$AS17/(1+($AR$111+시나리오!$A$8/10000)/2)^(AZ17-1),0) | BO17: =IF(AY17=1,$AS17/(1+($AR$111+시나리오!$A$9/10000)/2)^(AZ17-1),0) | BP17: =IF(AY17=1,$AS17/(1+($AR$111+시나리오!$A$10/10000)/2)^(AZ17-1),0) | BQ17: =IF(AY17=1,$AS17/(1+($AR$111+시나리오!$A$11/10000)/2)^(AZ17-1),0) | BR17: =IF(AY17=1,$AS17/(1+($AR$111+시나리오!$A$12/10000)/2)^(AZ17-1),0) | BS17: =IF(AY17=1,$AS17/(1+($AR$111+시나리오!$A$13/10000)/2)^(AZ17-1),0) | BT17: =IF(AY17=1,$AS17/(1+($AR$111+시나리오!$A$14/10000)/2)^(AZ17-1),0) | BU17: =IF(AY17=1,$AS17/(1+($AR$111+시나리오!$A$15/10000)/2)^(AZ17-1),0) | BV17: =IF(AY17=1,$AS17/(1+($AR$111+시나리오!$A$16/10000)/2)^(AZ17-1),0) | BW17: =IF(AY17=1,$AS17/(1+($AR$111+시나리오!$A$17/10000)/2)^(AZ17-1),0) | BX17: =IF(AY17=1,$AS17/(1+($AR$111+시나리오!$A$18/10000)/2)^(AZ17-1),0) | BY17: =IF(AY17=1,$AS17/(1+($AR$111+시나리오!$A$19/10000)/2)^(AZ17-1),0) | BZ17: =IF(AY17=1,$AS17/(1+($AR$111+시나리오!$A$20/10000)/2)^(AZ17-1),0) | CA17: =IF(AY17=1,$AS17/(1+($AR$111+시나리오!$A$21/10000)/2)^(AZ17-1),0) | CB17: =IF(AY17=1,$AS17/(1+($AR$111+시나리오!$A$22/10000)/2)^(AZ17-1),0) | CC17: =IF(AY17=1,$AS17/(1+($AR$111+시나리오!$A$23/10000)/2)^(AZ17-1),0) | CD17: =IF(AY17=1,$AS17/(1+($AR$111+시나리오!$A$24/10000)/2)^(AZ17-1),0) | CG17: 3 | CH17: =EDATE($CH$2,-6*(62-$CG17)) | CI17: =IF(AND(CH17>$CH$3,CH17<=$CH$2),IF(CH17=$CH$2,$CH$5+100,$CH$5),0) | CJ17: =IF(AND($CI17>0,CH17>$CH$6),1,0) | CK17: =IF(CJ17=1,SUM($CJ$15:CJ17),"") | CL17: =IF(CJ17=1,$CI17/(1+$CH$8/2)^(CK17-1),0) | CM17: =IF(CJ17=1,$CI17/(1+($CH$8+0.0001)/2)^(CK17-1),0) | CN17: =IF(CJ17=1,$CI17/(1+($CH$8-0.0001)/2)^(CK17-1),0) | CO17: =IF(AND($CI17>0,CH17>$CH$7),1,0) | CP17: =IF(CO17=1,SUM($CO$15:CO17),"") | CQ17: =IF(CO17=1,$CI17/(1+$CH$104/2)^(CP17-1),0) | CR17: =IF(CO17=1,$CI17/(1+($CH$104+0.0001)/2)^(CP17-1),0) | CS17: =IF(CO17=1,$CI17/(1+($CH$104-0.0001)/2)^(CP17-1),0) | CT17: =IF(CO17=1,$CI17/(1+$CH$109/2)^(CP17-1),0) | CU17: =IF(CO17=1,$CI17/(1+$CH$111/2)^(CP17-1),0) | CV17: =IF(CO17=1,$CI17/(1+($CH$111+0.0001)/2)^(CP17-1),0) | CW17: =IF(CO17=1,$CI17/(1+($CH$111-0.0001)/2)^(CP17-1),0) | CX17: =IF(AND($CI17>0,CH17>$CH$6,CH17<=$CH$7),$CI17*(1+$CH$10*($CH$7-CH17)/365),0) | CY17: =IF(CO17=1,$CI17/(1+($CH$111+손익!$B$24/10000)/2)^(CP17-1),0) | CZ17: =IF(CO17=1,$CI17/(1+($CH$111+시나리오!$A$4/10000)/2)^(CP17-1),0) | DA17: =IF(CO17=1,$CI17/(1+($CH$111+시나리오!$A$5/10000)/2)^(CP17-1),0) | DB17: =IF(CO17=1,$CI17/(1+($CH$111+시나리오!$A$6/10000)/2)^(CP17-1),0) | DC17: =IF(CO17=1,$CI17/(1+($CH$111+시나리오!$A$7/10000)/2)^(CP17-1),0) | DD17: =IF(CO17=1,$CI17/(1+($CH$111+시나리오!$A$8/10000)/2)^(CP17-1),0) | DE17: =IF(CO17=1,$CI17/(1+($CH$111+시나리오!$A$9/10000)/2)^(CP17-1),0) | DF17: =IF(CO17=1,$CI17/(1+($CH$111+시나리오!$A$10/10000)/2)^(CP17-1),0) | DG17: =IF(CO17=1,$CI17/(1+($CH$111+시나리오!$A$11/10000)/2)^(CP17-1),0) | DH17: =IF(CO17=1,$CI17/(1+($CH$111+시나리오!$A$12/10000)/2)^(CP17-1),0) | DI17: =IF(CO17=1,$CI17/(1+($CH$111+시나리오!$A$13/10000)/2)^(CP17-1),0) | DJ17: =IF(CO17=1,$CI17/(1+($CH$111+시나리오!$A$14/10000)/2)^(CP17-1),0) | DK17: =IF(CO17=1,$CI17/(1+($CH$111+시나리오!$A$15/10000)/2)^(CP17-1),0) | DL17: =IF(CO17=1,$CI17/(1+($CH$111+시나리오!$A$16/10000)/2)^(CP17-1),0) | DM17: =IF(CO17=1,$CI17/(1+($CH$111+시나리오!$A$17/10000)/2)^(CP17-1),0) | DN17: =IF(CO17=1,$CI17/(1+($CH$111+시나리오!$A$18/10000)/2)^(CP17-1),0) | DO17: =IF(CO17=1,$CI17/(1+($CH$111+시나리오!$A$19/10000)/2)^(CP17-1),0) | DP17: =IF(CO17=1,$CI17/(1+($CH$111+시나리오!$A$20/10000)/2)^(CP17-1),0) | DQ17: =IF(CO17=1,$CI17/(1+($CH$111+시나리오!$A$21/10000)/2)^(CP17-1),0) | DR17: =IF(CO17=1,$CI17/(1+($CH$111+시나리오!$A$22/10000)/2)^(CP17-1),0) | DS17: =IF(CO17=1,$CI17/(1+($CH$111+시나리오!$A$23/10000)/2)^(CP17-1),0) | DT17: =IF(CO17=1,$CI17/(1+($CH$111+시나리오!$A$24/10000)/2)^(CP17-1),0)
A18: 4 | B18: =EDATE($B$2,-6*(62-$A18)) | C18: =IF(AND(B18>$B$3,B18<=$B$2),IF(B18=$B$2,$B$5+100,$B$5),0) | D18: =IF(AND($C18>0,B18>$B$6),1,0) | E18: =IF(D18=1,SUM($D$15:D18),"") | F18: =IF(D18=1,$C18/(1+$B$8/2)^(E18-1),0) | G18: =IF(D18=1,$C18/(1+($B$8+0.0001)/2)^(E18-1),0) | H18: =IF(D18=1,$C18/(1+($B$8-0.0001)/2)^(E18-1),0) | I18: =IF(AND($C18>0,B18>$B$7),1,0) | J18: =IF(I18=1,SUM($I$15:I18),"") | K18: =IF(I18=1,$C18/(1+$B$104/2)^(J18-1),0) | L18: =IF(I18=1,$C18/(1+($B$104+0.0001)/2)^(J18-1),0) | M18: =IF(I18=1,$C18/(1+($B$104-0.0001)/2)^(J18-1),0) | N18: =IF(I18=1,$C18/(1+$B$109/2)^(J18-1),0) | O18: =IF(I18=1,$C18/(1+$B$111/2)^(J18-1),0) | P18: =IF(I18=1,$C18/(1+($B$111+0.0001)/2)^(J18-1),0) | Q18: =IF(I18=1,$C18/(1+($B$111-0.0001)/2)^(J18-1),0) | R18: =IF(AND($C18>0,B18>$B$6,B18<=$B$7),$C18*(1+$B$10*($B$7-B18)/365),0) | S18: =IF(I18=1,$C18/(1+($B$111+손익!$B$24/10000)/2)^(J18-1),0) | T18: =IF(I18=1,$C18/(1+($B$111+시나리오!$A$4/10000)/2)^(J18-1),0) | U18: =IF(I18=1,$C18/(1+($B$111+시나리오!$A$5/10000)/2)^(J18-1),0) | V18: =IF(I18=1,$C18/(1+($B$111+시나리오!$A$6/10000)/2)^(J18-1),0) | W18: =IF(I18=1,$C18/(1+($B$111+시나리오!$A$7/10000)/2)^(J18-1),0) | X18: =IF(I18=1,$C18/(1+($B$111+시나리오!$A$8/10000)/2)^(J18-1),0) | Y18: =IF(I18=1,$C18/(1+($B$111+시나리오!$A$9/10000)/2)^(J18-1),0) | Z18: =IF(I18=1,$C18/(1+($B$111+시나리오!$A$10/10000)/2)^(J18-1),0) | AA18: =IF(I18=1,$C18/(1+($B$111+시나리오!$A$11/10000)/2)^(J18-1),0) | AB18: =IF(I18=1,$C18/(1+($B$111+시나리오!$A$12/10000)/2)^(J18-1),0) | AC18: =IF(I18=1,$C18/(1+($B$111+시나리오!$A$13/10000)/2)^(J18-1),0) | AD18: =IF(I18=1,$C18/(1+($B$111+시나리오!$A$14/10000)/2)^(J18-1),0) | AE18: =IF(I18=1,$C18/(1+($B$111+시나리오!$A$15/10000)/2)^(J18-1),0) | AF18: =IF(I18=1,$C18/(1+($B$111+시나리오!$A$16/10000)/2)^(J18-1),0) | AG18: =IF(I18=1,$C18/(1+($B$111+시나리오!$A$17/10000)/2)^(J18-1),0) | AH18: =IF(I18=1,$C18/(1+($B$111+시나리오!$A$18/10000)/2)^(J18-1),0) | AI18: =IF(I18=1,$C18/(1+($B$111+시나리오!$A$19/10000)/2)^(J18-1),0) | AJ18: =IF(I18=1,$C18/(1+($B$111+시나리오!$A$20/10000)/2)^(J18-1),0) | AK18: =IF(I18=1,$C18/(1+($B$111+시나리오!$A$21/10000)/2)^(J18-1),0) | AL18: =IF(I18=1,$C18/(1+($B$111+시나리오!$A$22/10000)/2)^(J18-1),0) | AM18: =IF(I18=1,$C18/(1+($B$111+시나리오!$A$23/10000)/2)^(J18-1),0) | AN18: =IF(I18=1,$C18/(1+($B$111+시나리오!$A$24/10000)/2)^(J18-1),0) | AQ18: 4 | AR18: =EDATE($AR$2,-6*(62-$AQ18)) | AS18: =IF(AND(AR18>$AR$3,AR18<=$AR$2),IF(AR18=$AR$2,$AR$5+100,$AR$5),0) | AT18: =IF(AND($AS18>0,AR18>$AR$6),1,0) | AU18: =IF(AT18=1,SUM($AT$15:AT18),"") | AV18: =IF(AT18=1,$AS18/(1+$AR$8/2)^(AU18-1),0) | AW18: =IF(AT18=1,$AS18/(1+($AR$8+0.0001)/2)^(AU18-1),0) | AX18: =IF(AT18=1,$AS18/(1+($AR$8-0.0001)/2)^(AU18-1),0) | AY18: =IF(AND($AS18>0,AR18>$AR$7),1,0) | AZ18: =IF(AY18=1,SUM($AY$15:AY18),"") | BA18: =IF(AY18=1,$AS18/(1+$AR$104/2)^(AZ18-1),0) | BB18: =IF(AY18=1,$AS18/(1+($AR$104+0.0001)/2)^(AZ18-1),0) | BC18: =IF(AY18=1,$AS18/(1+($AR$104-0.0001)/2)^(AZ18-1),0) | BD18: =IF(AY18=1,$AS18/(1+$AR$109/2)^(AZ18-1),0) | BE18: =IF(AY18=1,$AS18/(1+$AR$111/2)^(AZ18-1),0) | BF18: =IF(AY18=1,$AS18/(1+($AR$111+0.0001)/2)^(AZ18-1),0) | BG18: =IF(AY18=1,$AS18/(1+($AR$111-0.0001)/2)^(AZ18-1),0) | BH18: =IF(AND($AS18>0,AR18>$AR$6,AR18<=$AR$7),$AS18*(1+$AR$10*($AR$7-AR18)/365),0) | BI18: =IF(AY18=1,$AS18/(1+($AR$111+손익!$B$24/10000)/2)^(AZ18-1),0) | BJ18: =IF(AY18=1,$AS18/(1+($AR$111+시나리오!$A$4/10000)/2)^(AZ18-1),0) | BK18: =IF(AY18=1,$AS18/(1+($AR$111+시나리오!$A$5/10000)/2)^(AZ18-1),0) | BL18: =IF(AY18=1,$AS18/(1+($AR$111+시나리오!$A$6/10000)/2)^(AZ18-1),0) | BM18: =IF(AY18=1,$AS18/(1+($AR$111+시나리오!$A$7/10000)/2)^(AZ18-1),0) | BN18: =IF(AY18=1,$AS18/(1+($AR$111+시나리오!$A$8/10000)/2)^(AZ18-1),0) | BO18: =IF(AY18=1,$AS18/(1+($AR$111+시나리오!$A$9/10000)/2)^(AZ18-1),0) | BP18: =IF(AY18=1,$AS18/(1+($AR$111+시나리오!$A$10/10000)/2)^(AZ18-1),0) | BQ18: =IF(AY18=1,$AS18/(1+($AR$111+시나리오!$A$11/10000)/2)^(AZ18-1),0) | BR18: =IF(AY18=1,$AS18/(1+($AR$111+시나리오!$A$12/10000)/2)^(AZ18-1),0) | BS18: =IF(AY18=1,$AS18/(1+($AR$111+시나리오!$A$13/10000)/2)^(AZ18-1),0) | BT18: =IF(AY18=1,$AS18/(1+($AR$111+시나리오!$A$14/10000)/2)^(AZ18-1),0) | BU18: =IF(AY18=1,$AS18/(1+($AR$111+시나리오!$A$15/10000)/2)^(AZ18-1),0) | BV18: =IF(AY18=1,$AS18/(1+($AR$111+시나리오!$A$16/10000)/2)^(AZ18-1),0) | BW18: =IF(AY18=1,$AS18/(1+($AR$111+시나리오!$A$17/10000)/2)^(AZ18-1),0) | BX18: =IF(AY18=1,$AS18/(1+($AR$111+시나리오!$A$18/10000)/2)^(AZ18-1),0) | BY18: =IF(AY18=1,$AS18/(1+($AR$111+시나리오!$A$19/10000)/2)^(AZ18-1),0) | BZ18: =IF(AY18=1,$AS18/(1+($AR$111+시나리오!$A$20/10000)/2)^(AZ18-1),0) | CA18: =IF(AY18=1,$AS18/(1+($AR$111+시나리오!$A$21/10000)/2)^(AZ18-1),0) | CB18: =IF(AY18=1,$AS18/(1+($AR$111+시나리오!$A$22/10000)/2)^(AZ18-1),0) | CC18: =IF(AY18=1,$AS18/(1+($AR$111+시나리오!$A$23/10000)/2)^(AZ18-1),0) | CD18: =IF(AY18=1,$AS18/(1+($AR$111+시나리오!$A$24/10000)/2)^(AZ18-1),0) | CG18: 4 | CH18: =EDATE($CH$2,-6*(62-$CG18)) | CI18: =IF(AND(CH18>$CH$3,CH18<=$CH$2),IF(CH18=$CH$2,$CH$5+100,$CH$5),0) | CJ18: =IF(AND($CI18>0,CH18>$CH$6),1,0) | CK18: =IF(CJ18=1,SUM($CJ$15:CJ18),"") | CL18: =IF(CJ18=1,$CI18/(1+$CH$8/2)^(CK18-1),0) | CM18: =IF(CJ18=1,$CI18/(1+($CH$8+0.0001)/2)^(CK18-1),0) | CN18: =IF(CJ18=1,$CI18/(1+($CH$8-0.0001)/2)^(CK18-1),0) | CO18: =IF(AND($CI18>0,CH18>$CH$7),1,0) | CP18: =IF(CO18=1,SUM($CO$15:CO18),"") | CQ18: =IF(CO18=1,$CI18/(1+$CH$104/2)^(CP18-1),0) | CR18: =IF(CO18=1,$CI18/(1+($CH$104+0.0001)/2)^(CP18-1),0) | CS18: =IF(CO18=1,$CI18/(1+($CH$104-0.0001)/2)^(CP18-1),0) | CT18: =IF(CO18=1,$CI18/(1+$CH$109/2)^(CP18-1),0) | CU18: =IF(CO18=1,$CI18/(1+$CH$111/2)^(CP18-1),0) | CV18: =IF(CO18=1,$CI18/(1+($CH$111+0.0001)/2)^(CP18-1),0) | CW18: =IF(CO18=1,$CI18/(1+($CH$111-0.0001)/2)^(CP18-1),0) | CX18: =IF(AND($CI18>0,CH18>$CH$6,CH18<=$CH$7),$CI18*(1+$CH$10*($CH$7-CH18)/365),0) | CY18: =IF(CO18=1,$CI18/(1+($CH$111+손익!$B$24/10000)/2)^(CP18-1),0) | CZ18: =IF(CO18=1,$CI18/(1+($CH$111+시나리오!$A$4/10000)/2)^(CP18-1),0) | DA18: =IF(CO18=1,$CI18/(1+($CH$111+시나리오!$A$5/10000)/2)^(CP18-1),0) | DB18: =IF(CO18=1,$CI18/(1+($CH$111+시나리오!$A$6/10000)/2)^(CP18-1),0) | DC18: =IF(CO18=1,$CI18/(1+($CH$111+시나리오!$A$7/10000)/2)^(CP18-1),0) | DD18: =IF(CO18=1,$CI18/(1+($CH$111+시나리오!$A$8/10000)/2)^(CP18-1),0) | DE18: =IF(CO18=1,$CI18/(1+($CH$111+시나리오!$A$9/10000)/2)^(CP18-1),0) | DF18: =IF(CO18=1,$CI18/(1+($CH$111+시나리오!$A$10/10000)/2)^(CP18-1),0) | DG18: =IF(CO18=1,$CI18/(1+($CH$111+시나리오!$A$11/10000)/2)^(CP18-1),0) | DH18: =IF(CO18=1,$CI18/(1+($CH$111+시나리오!$A$12/10000)/2)^(CP18-1),0) | DI18: =IF(CO18=1,$CI18/(1+($CH$111+시나리오!$A$13/10000)/2)^(CP18-1),0) | DJ18: =IF(CO18=1,$CI18/(1+($CH$111+시나리오!$A$14/10000)/2)^(CP18-1),0) | DK18: =IF(CO18=1,$CI18/(1+($CH$111+시나리오!$A$15/10000)/2)^(CP18-1),0) | DL18: =IF(CO18=1,$CI18/(1+($CH$111+시나리오!$A$16/10000)/2)^(CP18-1),0) | DM18: =IF(CO18=1,$CI18/(1+($CH$111+시나리오!$A$17/10000)/2)^(CP18-1),0) | DN18: =IF(CO18=1,$CI18/(1+($CH$111+시나리오!$A$18/10000)/2)^(CP18-1),0) | DO18: =IF(CO18=1,$CI18/(1+($CH$111+시나리오!$A$19/10000)/2)^(CP18-1),0) | DP18: =IF(CO18=1,$CI18/(1+($CH$111+시나리오!$A$20/10000)/2)^(CP18-1),0) | DQ18: =IF(CO18=1,$CI18/(1+($CH$111+시나리오!$A$21/10000)/2)^(CP18-1),0) | DR18: =IF(CO18=1,$CI18/(1+($CH$111+시나리오!$A$22/10000)/2)^(CP18-1),0) | DS18: =IF(CO18=1,$CI18/(1+($CH$111+시나리오!$A$23/10000)/2)^(CP18-1),0) | DT18: =IF(CO18=1,$CI18/(1+($CH$111+시나리오!$A$24/10000)/2)^(CP18-1),0)
A19: 5 | B19: =EDATE($B$2,-6*(62-$A19)) | C19: =IF(AND(B19>$B$3,B19<=$B$2),IF(B19=$B$2,$B$5+100,$B$5),0) | D19: =IF(AND($C19>0,B19>$B$6),1,0) | E19: =IF(D19=1,SUM($D$15:D19),"") | F19: =IF(D19=1,$C19/(1+$B$8/2)^(E19-1),0) | G19: =IF(D19=1,$C19/(1+($B$8+0.0001)/2)^(E19-1),0) | H19: =IF(D19=1,$C19/(1+($B$8-0.0001)/2)^(E19-1),0) | I19: =IF(AND($C19>0,B19>$B$7),1,0) | J19: =IF(I19=1,SUM($I$15:I19),"") | K19: =IF(I19=1,$C19/(1+$B$104/2)^(J19-1),0) | L19: =IF(I19=1,$C19/(1+($B$104+0.0001)/2)^(J19-1),0) | M19: =IF(I19=1,$C19/(1+($B$104-0.0001)/2)^(J19-1),0) | N19: =IF(I19=1,$C19/(1+$B$109/2)^(J19-1),0) | O19: =IF(I19=1,$C19/(1+$B$111/2)^(J19-1),0) | P19: =IF(I19=1,$C19/(1+($B$111+0.0001)/2)^(J19-1),0) | Q19: =IF(I19=1,$C19/(1+($B$111-0.0001)/2)^(J19-1),0) | R19: =IF(AND($C19>0,B19>$B$6,B19<=$B$7),$C19*(1+$B$10*($B$7-B19)/365),0) | S19: =IF(I19=1,$C19/(1+($B$111+손익!$B$24/10000)/2)^(J19-1),0) | T19: =IF(I19=1,$C19/(1+($B$111+시나리오!$A$4/10000)/2)^(J19-1),0) | U19: =IF(I19=1,$C19/(1+($B$111+시나리오!$A$5/10000)/2)^(J19-1),0) | V19: =IF(I19=1,$C19/(1+($B$111+시나리오!$A$6/10000)/2)^(J19-1),0) | W19: =IF(I19=1,$C19/(1+($B$111+시나리오!$A$7/10000)/2)^(J19-1),0) | X19: =IF(I19=1,$C19/(1+($B$111+시나리오!$A$8/10000)/2)^(J19-1),0) | Y19: =IF(I19=1,$C19/(1+($B$111+시나리오!$A$9/10000)/2)^(J19-1),0) | Z19: =IF(I19=1,$C19/(1+($B$111+시나리오!$A$10/10000)/2)^(J19-1),0) | AA19: =IF(I19=1,$C19/(1+($B$111+시나리오!$A$11/10000)/2)^(J19-1),0) | AB19: =IF(I19=1,$C19/(1+($B$111+시나리오!$A$12/10000)/2)^(J19-1),0) | AC19: =IF(I19=1,$C19/(1+($B$111+시나리오!$A$13/10000)/2)^(J19-1),0) | AD19: =IF(I19=1,$C19/(1+($B$111+시나리오!$A$14/10000)/2)^(J19-1),0) | AE19: =IF(I19=1,$C19/(1+($B$111+시나리오!$A$15/10000)/2)^(J19-1),0) | AF19: =IF(I19=1,$C19/(1+($B$111+시나리오!$A$16/10000)/2)^(J19-1),0) | AG19: =IF(I19=1,$C19/(1+($B$111+시나리오!$A$17/10000)/2)^(J19-1),0) | AH19: =IF(I19=1,$C19/(1+($B$111+시나리오!$A$18/10000)/2)^(J19-1),0) | AI19: =IF(I19=1,$C19/(1+($B$111+시나리오!$A$19/10000)/2)^(J19-1),0) | AJ19: =IF(I19=1,$C19/(1+($B$111+시나리오!$A$20/10000)/2)^(J19-1),0) | AK19: =IF(I19=1,$C19/(1+($B$111+시나리오!$A$21/10000)/2)^(J19-1),0) | AL19: =IF(I19=1,$C19/(1+($B$111+시나리오!$A$22/10000)/2)^(J19-1),0) | AM19: =IF(I19=1,$C19/(1+($B$111+시나리오!$A$23/10000)/2)^(J19-1),0) | AN19: =IF(I19=1,$C19/(1+($B$111+시나리오!$A$24/10000)/2)^(J19-1),0) | AQ19: 5 | AR19: =EDATE($AR$2,-6*(62-$AQ19)) | AS19: =IF(AND(AR19>$AR$3,AR19<=$AR$2),IF(AR19=$AR$2,$AR$5+100,$AR$5),0) | AT19: =IF(AND($AS19>0,AR19>$AR$6),1,0) | AU19: =IF(AT19=1,SUM($AT$15:AT19),"") | AV19: =IF(AT19=1,$AS19/(1+$AR$8/2)^(AU19-1),0) | AW19: =IF(AT19=1,$AS19/(1+($AR$8+0.0001)/2)^(AU19-1),0) | AX19: =IF(AT19=1,$AS19/(1+($AR$8-0.0001)/2)^(AU19-1),0) | AY19: =IF(AND($AS19>0,AR19>$AR$7),1,0) | AZ19: =IF(AY19=1,SUM($AY$15:AY19),"") | BA19: =IF(AY19=1,$AS19/(1+$AR$104/2)^(AZ19-1),0) | BB19: =IF(AY19=1,$AS19/(1+($AR$104+0.0001)/2)^(AZ19-1),0) | BC19: =IF(AY19=1,$AS19/(1+($AR$104-0.0001)/2)^(AZ19-1),0) | BD19: =IF(AY19=1,$AS19/(1+$AR$109/2)^(AZ19-1),0) | BE19: =IF(AY19=1,$AS19/(1+$AR$111/2)^(AZ19-1),0) | BF19: =IF(AY19=1,$AS19/(1+($AR$111+0.0001)/2)^(AZ19-1),0) | BG19: =IF(AY19=1,$AS19/(1+($AR$111-0.0001)/2)^(AZ19-1),0) | BH19: =IF(AND($AS19>0,AR19>$AR$6,AR19<=$AR$7),$AS19*(1+$AR$10*($AR$7-AR19)/365),0) | BI19: =IF(AY19=1,$AS19/(1+($AR$111+손익!$B$24/10000)/2)^(AZ19-1),0) | BJ19: =IF(AY19=1,$AS19/(1+($AR$111+시나리오!$A$4/10000)/2)^(AZ19-1),0) | BK19: =IF(AY19=1,$AS19/(1+($AR$111+시나리오!$A$5/10000)/2)^(AZ19-1),0) | BL19: =IF(AY19=1,$AS19/(1+($AR$111+시나리오!$A$6/10000)/2)^(AZ19-1),0) | BM19: =IF(AY19=1,$AS19/(1+($AR$111+시나리오!$A$7/10000)/2)^(AZ19-1),0) | BN19: =IF(AY19=1,$AS19/(1+($AR$111+시나리오!$A$8/10000)/2)^(AZ19-1),0) | BO19: =IF(AY19=1,$AS19/(1+($AR$111+시나리오!$A$9/10000)/2)^(AZ19-1),0) | BP19: =IF(AY19=1,$AS19/(1+($AR$111+시나리오!$A$10/10000)/2)^(AZ19-1),0) | BQ19: =IF(AY19=1,$AS19/(1+($AR$111+시나리오!$A$11/10000)/2)^(AZ19-1),0) | BR19: =IF(AY19=1,$AS19/(1+($AR$111+시나리오!$A$12/10000)/2)^(AZ19-1),0) | BS19: =IF(AY19=1,$AS19/(1+($AR$111+시나리오!$A$13/10000)/2)^(AZ19-1),0) | BT19: =IF(AY19=1,$AS19/(1+($AR$111+시나리오!$A$14/10000)/2)^(AZ19-1),0) | BU19: =IF(AY19=1,$AS19/(1+($AR$111+시나리오!$A$15/10000)/2)^(AZ19-1),0) | BV19: =IF(AY19=1,$AS19/(1+($AR$111+시나리오!$A$16/10000)/2)^(AZ19-1),0) | BW19: =IF(AY19=1,$AS19/(1+($AR$111+시나리오!$A$17/10000)/2)^(AZ19-1),0) | BX19: =IF(AY19=1,$AS19/(1+($AR$111+시나리오!$A$18/10000)/2)^(AZ19-1),0) | BY19: =IF(AY19=1,$AS19/(1+($AR$111+시나리오!$A$19/10000)/2)^(AZ19-1),0) | BZ19: =IF(AY19=1,$AS19/(1+($AR$111+시나리오!$A$20/10000)/2)^(AZ19-1),0) | CA19: =IF(AY19=1,$AS19/(1+($AR$111+시나리오!$A$21/10000)/2)^(AZ19-1),0) | CB19: =IF(AY19=1,$AS19/(1+($AR$111+시나리오!$A$22/10000)/2)^(AZ19-1),0) | CC19: =IF(AY19=1,$AS19/(1+($AR$111+시나리오!$A$23/10000)/2)^(AZ19-1),0) | CD19: =IF(AY19=1,$AS19/(1+($AR$111+시나리오!$A$24/10000)/2)^(AZ19-1),0) | CG19: 5 | CH19: =EDATE($CH$2,-6*(62-$CG19)) | CI19: =IF(AND(CH19>$CH$3,CH19<=$CH$2),IF(CH19=$CH$2,$CH$5+100,$CH$5),0) | CJ19: =IF(AND($CI19>0,CH19>$CH$6),1,0) | CK19: =IF(CJ19=1,SUM($CJ$15:CJ19),"") | CL19: =IF(CJ19=1,$CI19/(1+$CH$8/2)^(CK19-1),0) | CM19: =IF(CJ19=1,$CI19/(1+($CH$8+0.0001)/2)^(CK19-1),0) | CN19: =IF(CJ19=1,$CI19/(1+($CH$8-0.0001)/2)^(CK19-1),0) | CO19: =IF(AND($CI19>0,CH19>$CH$7),1,0) | CP19: =IF(CO19=1,SUM($CO$15:CO19),"") | CQ19: =IF(CO19=1,$CI19/(1+$CH$104/2)^(CP19-1),0) | CR19: =IF(CO19=1,$CI19/(1+($CH$104+0.0001)/2)^(CP19-1),0) | CS19: =IF(CO19=1,$CI19/(1+($CH$104-0.0001)/2)^(CP19-1),0) | CT19: =IF(CO19=1,$CI19/(1+$CH$109/2)^(CP19-1),0) | CU19: =IF(CO19=1,$CI19/(1+$CH$111/2)^(CP19-1),0) | CV19: =IF(CO19=1,$CI19/(1+($CH$111+0.0001)/2)^(CP19-1),0) | CW19: =IF(CO19=1,$CI19/(1+($CH$111-0.0001)/2)^(CP19-1),0) | CX19: =IF(AND($CI19>0,CH19>$CH$6,CH19<=$CH$7),$CI19*(1+$CH$10*($CH$7-CH19)/365),0) | CY19: =IF(CO19=1,$CI19/(1+($CH$111+손익!$B$24/10000)/2)^(CP19-1),0) | CZ19: =IF(CO19=1,$CI19/(1+($CH$111+시나리오!$A$4/10000)/2)^(CP19-1),0) | DA19: =IF(CO19=1,$CI19/(1+($CH$111+시나리오!$A$5/10000)/2)^(CP19-1),0) | DB19: =IF(CO19=1,$CI19/(1+($CH$111+시나리오!$A$6/10000)/2)^(CP19-1),0) | DC19: =IF(CO19=1,$CI19/(1+($CH$111+시나리오!$A$7/10000)/2)^(CP19-1),0) | DD19: =IF(CO19=1,$CI19/(1+($CH$111+시나리오!$A$8/10000)/2)^(CP19-1),0) | DE19: =IF(CO19=1,$CI19/(1+($CH$111+시나리오!$A$9/10000)/2)^(CP19-1),0) | DF19: =IF(CO19=1,$CI19/(1+($CH$111+시나리오!$A$10/10000)/2)^(CP19-1),0) | DG19: =IF(CO19=1,$CI19/(1+($CH$111+시나리오!$A$11/10000)/2)^(CP19-1),0) | DH19: =IF(CO19=1,$CI19/(1+($CH$111+시나리오!$A$12/10000)/2)^(CP19-1),0) | DI19: =IF(CO19=1,$CI19/(1+($CH$111+시나리오!$A$13/10000)/2)^(CP19-1),0) | DJ19: =IF(CO19=1,$CI19/(1+($CH$111+시나리오!$A$14/10000)/2)^(CP19-1),0) | DK19: =IF(CO19=1,$CI19/(1+($CH$111+시나리오!$A$15/10000)/2)^(CP19-1),0) | DL19: =IF(CO19=1,$CI19/(1+($CH$111+시나리오!$A$16/10000)/2)^(CP19-1),0) | DM19: =IF(CO19=1,$CI19/(1+($CH$111+시나리오!$A$17/10000)/2)^(CP19-1),0) | DN19: =IF(CO19=1,$CI19/(1+($CH$111+시나리오!$A$18/10000)/2)^(CP19-1),0) | DO19: =IF(CO19=1,$CI19/(1+($CH$111+시나리오!$A$19/10000)/2)^(CP19-1),0) | DP19: =IF(CO19=1,$CI19/(1+($CH$111+시나리오!$A$20/10000)/2)^(CP19-1),0) | DQ19: =IF(CO19=1,$CI19/(1+($CH$111+시나리오!$A$21/10000)/2)^(CP19-1),0) | DR19: =IF(CO19=1,$CI19/(1+($CH$111+시나리오!$A$22/10000)/2)^(CP19-1),0) | DS19: =IF(CO19=1,$CI19/(1+($CH$111+시나리오!$A$23/10000)/2)^(CP19-1),0) | DT19: =IF(CO19=1,$CI19/(1+($CH$111+시나리오!$A$24/10000)/2)^(CP19-1),0)
