Workbook

Sheet 메인
A1: 국채선물(10년) 차익거래 — 실시간 만기손익
A3: [1] 설정 ◆ 노란 셀만 입력하십시오
A4: 결제월 (YYYYMM) | B4: 202609 | F4: 3/6/9/12월물
A5: 최종거래일 (자동: 셋째 화요일) | B5: =DATE(INT(B4/100),MOD(B4,100),1)+MOD(2-WEEKDAY(DATE(INT(B4/100),MOD(B4,100),1),2)+7,7)+14
A6: 최종거래일 (수동 우선) | F6: 공휴일 조정 시 입력
A7: ▶ 최종거래일 | B7: =IF(B6="",B5,B6)
A8: ▶ 정산기준일 H | B8: =WORKDAY(B7,1) | F8: 현물 청산 T+1 결제일
A9: 현재일 | B9: =TODAY()
A10: ▶ 현물결제일 S0 | B10: =WORKDAY(B9,1) | F10: 국고채 익일결제
A11: 보유일수 (S0 → H) | B11: =B8-B10 | C11: 일
A12: 조달금리 — 바스켓 매수 시 지급 | B12: 2.6 | C12: % | F12: 레포(RP) 조달금리. 매수차익거래(바스켓매수+선물매도)에서 적용
A13: 담보운용금리 — 바스켓 매도 시 수취 | B13: 2.9 | C13: % | F13: 역RP 운용금리. 매도차익거래(바스켓매도+선물매수)에서 적용
A14: 표준물 만기 | B14: 10 | C14: 년 | F14: 10년물 고정
A15: 표준물 표면금리 | B15: 0.05 | F15: KRX 규격 5%
A16: 1포인트 가치 | B16: 1000000 | C16: 원 | F16: 액면 1억 ÷ 100
A17: 계약수 Q | B17: 100 | C17: 계약
A18: 포지션 방향 | B18: 매수차익 (바스켓매수+선물매도) | F18: 매수차익 = 바스켓매수+선물매도 / 매도차익 = 바스켓매도+선물매수
A19: 방향계수 | B19: =IF(LEFT($B$18,4)="매수차익",1,-1)
A20: 선물 진입가 | F20: 빈칸이면 현재가 사용
A21: ▶ 적용 진입가 | B21: =IF(B20="",B25,B20)
A22: 거래비용 | B22: 13000 | C22: 원/계약 | F22: 선물수수료 + 채권 스프레드 + 슬리피지
A23: 대차수수료 (매도차익 시에만) | B23: 0 | C23: bp | F23: 바스켓을 빌려서 파는 매도차익거래에만 적용. 매수차익거래에서는 무시된다 (산 채권을 대차로 빌려주는 것은 별도 영업이며, special 이점은 조달금리 B12 에 이미 반영됨)
A24: [2] 실시간 — 연합인포맥스 ◆ 붉은 셀이 IMDP 연결
A25: 선물 현재가 | B25: =_xll.IMDP("FUT",$B$26,"선물호가_현재가")
A26: 선물 종목코드 | B26: A6769000 | F26: 최근월물 코드로 갱신
A27: 종목1 수익률 | B27: =_xll.IMDP("BND",$C$34,"장내국채-매도수익률1") | C27: % | F27: 코드 인수를 셀참조로 씀. 오류 시 코드를 수식에 직접 입력
A28: 종목2 수익률 | B28: =_xll.IMDP("BND",$D$34,"장내국채-매도수익률1") | C28: %
A29: 인포맥스 이론가 (참고) | B29: =_xll.IMDP("FUT",$B$26,"이론가") | F29: B26과 같은 종목코드를 써야 비교가 유효
A30: ※ 종목1을 실시간으로 못 받으면 B27 을 =B28-2.6/100 처럼 스프레드 파생식으로 바꾸십시오 (원본 파일 방식). 단 스프레드는 수동 갱신이 필요합니다.
A31: ▶ 적용금리 (방향 반영) | B31: =IF($B$19=1,$B$12,$B$13-$B$23/100) | C31: % | F31: 매수차익 → 조달금리 B12 그대로. 매도차익 → 담보운용금리 B13 − 대차수수료 B23
A32: [3] 바스켓 (2종목)
A33: 항목 | B33: 단위 | C33: 종목1 | D33: 종목2 | E33: 합계
A34: 종목코드 | C34: KR103502GE97 | D34: KR103503GG60
A35: 종목명 | C35: 국고 25-5 | D35: 국고 25-11
A36: 표면금리 | B36: % | C36: 2.625 | D36: 3.25
A37: 발행일 | C37: 45818 | D37: 46001
A38: 만기일 | C38: 49470 | D38: 49653 | F38: 이표일을 여기서 6개월씩 역산
A39: 가중치 | C39: 0.5 | D39: 0.5 | E39: =SUM(C39:D39) | F39: KRX 최종결제기준가격은 단순평균 → 2종목이면 0.5
A40: 수익률 (실시간) | B40: % | C40: =B27 | D40: =B28
A41: 수익률 (소수) | C41: =C40/100 | D41: =D40/100
...

Sheet 엔진
A1: 계산 엔진 — 이표 스케줄 / 한국 관행식 단가 / 선도수익률 (직접 수정 금지)
A2: 만기일 | B2: =메인!C38 | AE2: 만기일 | AF2: =메인!D38
A3: 발행일 | B3: =메인!C37 | AE3: 발행일 | AF3: =메인!D37
A4: 표면금리(소수) | B4: =메인!C36/100 | AE4: 표면금리(소수) | AF4: =메인!D36/100
A5: 반기쿠폰 | B5: =B4*100/2 | AE5: 반기쿠폰 | AF5: =AF4*100/2
A6: 현물결제일 S0 | B6: =메인!$B$10 | AE6: 현물결제일 S0 | AF6: =메인!$B$10
A7: 정산기준일 H | B7: =메인!$B$8 | AE7: 정산기준일 H | AF7: =메인!$B$8
A8: 현물수익률(소수) | B8: =메인!C41 | AE8: 현물수익률(소수) | AF8: =메인!D41
A9: 적용금리(소수) | B9: =메인!$B$31/100 | AE9: 적용금리(소수) | AF9: =메인!$B$31/100
A10: 손익 shift(bp) | B10: =메인!$B$83 | AE10: 손익 shift(bp) | AF10: =메인!$B$83
A12: ■ 종목1 | AE12: ■ 종목2
A14: k | B14: 이표일 | C14: CF | D14: 현물포함 | E14: 현물idx | F14: PV@y | G14: PV@y+ | H14: PV@y− | I14: 선도포함 | J14: 선도idx | K14: PH@y0 | L14: PH@y0+ | M14: PH@y0− | N14: PH@y1 | O14: PH@y1+ | P14: PH@y1− | Q14: PH@y2 | R14: 쿠폰FV | S14: PH@손익 | T14: PH@S1 | U14: PH@S2 | V14: PH@S3 | W14: PH@S4 | X14: PH@S5 | Y14: PH@S6 | Z14: PH@S7 | AA14: PH@S8 | AB14: PH@S9 | AE14: k | AF14: 이표일 | AG14: CF | AH14: 현물포함 | AI14: 현물idx | AJ14: PV@y | AK14: PV@y+ | AL14: PV@y− | AM14: 선도포함 | AN14: 선도idx | AO14: PH@y0 | AP14: PH@y0+ | AQ14: PH@y0− | AR14: PH@y1 | AS14: PH@y1+ | AT14: PH@y1− | AU14: PH@y2 | AV14: 쿠폰FV | AW14: PH@손익 | AX14: PH@S1 | AY14: PH@S2 | AZ14: PH@S3 | BA14: PH@S4 | BB14: PH@S5 | BC14: PH@S6 | BD14: PH@S7 | BE14: PH@S8 | BF14: PH@S9
A15: 1 | B15: =EDATE($B$2,-6*(62-$A15)) | C15: =IF(AND(B15>$B$3,B15<=$B$2),IF(B15=$B$2,$B$5+100,$B$5),0) | D15: =IF(AND($C15>0,B15>$B$6),1,0) | E15: =IF(D15=1,SUM($D$15:D15),"") | F15: =IF(D15=1,$C15/(1+$B$8/2)^(E15-1),0) | G15: =IF(D15=1,$C15/(1+($B$8+0.0001)/2)^(E15-1),0) | H15: =IF(D15=1,$C15/(1+($B$8-0.0001)/2)^(E15-1),0) | I15: =IF(AND($C15>0,B15>$B$7),1,0) | J15: =IF(I15=1,SUM($I$15:I15),"") | K15: =IF(I15=1,$C15/(1+$B$99/2)^(J15-1),0) | L15: =IF(I15=1,$C15/(1+($B$99+0.0001)/2)^(J15-1),0) | M15: =IF(I15=1,$C15/(1+($B$99-0.0001)/2)^(J15-1),0) | N15: =IF(I15=1,$C15/(1+$B$104/2)^(J15-1),0) | O15: =IF(I15=1,$C15/(1+($B$104+0.0001)/2)^(J15-1),0) | P15: =IF(I15=1,$C15/(1+($B$104-0.0001)/2)^(J15-1),0) | Q15: =IF(I15=1,$C15/(1+$B$109/2)^(J15-1),0) | R15: =IF(AND($C15>0,B15>$B$6,B15<=$B$7),$C15*(1+$B$9*($B$7-B15)/365),0) | S15: =IF(I15=1,$C15/(1+($B$8+$B$10/10000)/2)^(J15-1),0) | T15: =IF(I15=1,$C15/(1+($B$8+메인!$A$96/10000)/2)^(J15-1),0) | U15: =IF(I15=1,$C15/(1+($B$8+메인!$A$97/10000)/2)^(J15-1),0) | V15: =IF(I15=1,$C15/(1+($B$8+메인!$A$98/10000)/2)^(J15-1),0) | W15: =IF(I15=1,$C15/(1+($B$8+메인!$A$99/10000)/2)^(J15-1),0) | X15: =IF(I15=1,$C15/(1+($B$8+메인!$A$100/10000)/2)^(J15-1),0) | Y15: =IF(I15=1,$C15/(1+($B$8+메인!$A$101/10000)/2)^(J15-1),0) | Z15: =IF(I15=1,$C15/(1+($B$8+메인!$A$102/10000)/2)^(J15-1),0) | AA15: =IF(I15=1,$C15/(1+($B$8+메인!$A$103/10000)/2)^(J15-1),0) | AB15: =IF(I15=1,$C15/(1+($B$8+메인!$A$104/10000)/2)^(J15-1),0) | AE15: 1 | AF15: =EDATE($AF$2,-6*(62-$AE15)) | AG15: =IF(AND(AF15>$AF$3,AF15<=$AF$2),IF(AF15=$AF$2,$AF$5+100,$AF$5),0) | AH15: =IF(AND($AG15>0,AF15>$AF$6),1,0) | AI15: =IF(AH15=1,SUM($AH$15:AH15),"") | AJ15: =IF(AH15=1,$AG15/(1+$AF$8/2)^(AI15-1),0) | AK15: =IF(AH15=1,$AG15/(1+($AF$8+0.0001)/2)^(AI15-1),0) | AL15: =IF(AH15=1,$AG15/(1+($AF$8-0.0001)/2)^(AI15-1),0) | AM15: =IF(AND($AG15>0,AF15>$AF$7),1,0) | AN15: =IF(AM15=1,SUM($AM$15:AM15),"") | AO15: =IF(AM15=1,$AG15/(1+$AF$99/2)^(AN15-1),0) | AP15: =IF(AM15=1,$AG15/(1+($AF$99+0.0001)/2)^(AN15-1),0) | AQ15: =IF(AM15=1,$AG15/(1+($AF$99-0.0001)/2)^(AN15-1),0) | AR15: =IF(AM15=1,$AG15/(1+$AF$104/2)^(AN15-1),0) | AS15: =IF(AM15=1,$AG15/(1+($AF$104+0.0001)/2)^(AN15-1),0) | AT15: =IF(AM15=1,$AG15/(1+($AF$104-0.0001)/2)^(AN15-1),0) | AU15: =IF(AM15=1,$AG15/(1+$AF$109/2)^(AN15-1),0) | AV15: =IF(AND($AG15>0,AF15>$AF$6,AF15<=$AF$7),$AG15*(1+$AF$9*($AF$7-AF15)/365),0) | AW15: =IF(AM15=1,$AG15/(1+($AF$8+$AF$10/10000)/2)^(AN15-1),0) | AX15: =IF(AM15=1,$AG15/(1+($AF$8+메인!$A$96/10000)/2)^(AN15-1),0) | AY15: =IF(AM15=1,$AG15/(1+($AF$8+메인!$A$97/10000)/2)^(AN15-1),0) | AZ15: =IF(AM15=1,$AG15/(1+($AF$8+메인!$A$98/10000)/2)^(AN15-1),0) | BA15: =IF(AM15=1,$AG15/(1+($AF$8+메인!$A$99/10000)/2)^(AN15-1),0) | BB15: =IF(AM15=1,$AG15/(1+($AF$8+메인!$A$100/10000)/2)^(AN15-1),0) | BC15: =IF(AM15=1,$AG15/(1+($AF$8+메인!$A$101/10000)/2)^(AN15-1),0) | BD15: =IF(AM15=1,$AG15/(1+($AF$8+메인!$A$102/10000)/2)^(AN15-1),0) | BE15: =IF(AM15=1,$AG15/(1+($AF$8+메인!$A$103/10000)/2)^(AN15-1),0) | BF15: =IF(AM15=1,$AG15/(1+($AF$8+메인!$A$104/10000)/2)^(AN15-1),0)
A16: 2 | B16: =EDATE($B$2,-6*(62-$A16)) | C16: =IF(AND(B16>$B$3,B16<=$B$2),IF(B16=$B$2,$B$5+100,$B$5),0) | D16: =IF(AND($C16>0,B16>$B$6),1,0) | E16: =IF(D16=1,SUM($D$15:D16),"") | F16: =IF(D16=1,$C16/(1+$B$8/2)^(E16-1),0) | G16: =IF(D16=1,$C16/(1+($B$8+0.0001)/2)^(E16-1),0) | H16: =IF(D16=1,$C16/(1+($B$8-0.0001)/2)^(E16-1),0) | I16: =IF(AND($C16>0,B16>$B$7),1,0) | J16: =IF(I16=1,SUM($I$15:I16),"") | K16: =IF(I16=1,$C16/(1+$B$99/2)^(J16-1),0) | L16: =IF(I16=1,$C16/(1+($B$99+0.0001)/2)^(J16-1),0) | M16: =IF(I16=1,$C16/(1+($B$99-0.0001)/2)^(J16-1),0) | N16: =IF(I16=1,$C16/(1+$B$104/2)^(J16-1),0) | O16: =IF(I16=1,$C16/(1+($B$104+0.0001)/2)^(J16-1),0) | P16: =IF(I16=1,$C16/(1+($B$104-0.0001)/2)^(J16-1),0) | Q16: =IF(I16=1,$C16/(1+$B$109/2)^(J16-1),0) | R16: =IF(AND($C16>0,B16>$B$6,B16<=$B$7),$C16*(1+$B$9*($B$7-B16)/365),0) | S16: =IF(I16=1,$C16/(1+($B$8+$B$10/10000)/2)^(J16-1),0) | T16: =IF(I16=1,$C16/(1+($B$8+메인!$A$96/10000)/2)^(J16-1),0) | U16: =IF(I16=1,$C16/(1+($B$8+메인!$A$97/10000)/2)^(J16-1),0) | V16: =IF(I16=1,$C16/(1+($B$8+메인!$A$98/10000)/2)^(J16-1),0) | W16: =IF(I16=1,$C16/(1+($B$8+메인!$A$99/10000)/2)^(J16-1),0) | X16: =IF(I16=1,$C16/(1+($B$8+메인!$A$100/10000)/2)^(J16-1),0) | Y16: =IF(I16=1,$C16/(1+($B$8+메인!$A$101/10000)/2)^(J16-1),0) | Z16: =IF(I16=1,$C16/(1+($B$8+메인!$A$102/10000)/2)^(J16-1),0) | AA16: =IF(I16=1,$C16/(1+($B$8+메인!$A$103/10000)/2)^(J16-1),0) | AB16: =IF(I16=1,$C16/(1+($B$8+메인!$A$104/10000)/2)^(J16-1),0) | AE16: 2 | AF16: =EDATE($AF$2,-6*(62-$AE16)) | AG16: =IF(AND(AF16>$AF$3,AF16<=$AF$2),IF(AF16=$AF$2,$AF$5+100,$AF$5),0) | AH16: =IF(AND($AG16>0,AF16>$AF$6),1,0) | AI16: =IF(AH16=1,SUM($AH$15:AH16),"") | AJ16: =IF(AH16=1,$AG16/(1+$AF$8/2)^(AI16-1),0) | AK16: =IF(AH16=1,$AG16/(1+($AF$8+0.0001)/2)^(AI16-1),0) | AL16: =IF(AH16=1,$AG16/(1+($AF$8-0.0001)/2)^(AI16-1),0) | AM16: =IF(AND($AG16>0,AF16>$AF$7),1,0) | AN16: =IF(AM16=1,SUM($AM$15:AM16),"") | AO16: =IF(AM16=1,$AG16/(1+$AF$99/2)^(AN16-1),0) | AP16: =IF(AM16=1,$AG16/(1+($AF$99+0.0001)/2)^(AN16-1),0) | AQ16: =IF(AM16=1,$AG16/(1+($AF$99-0.0001)/2)^(AN16-1),0) | AR16: =IF(AM16=1,$AG16/(1+$AF$104/2)^(AN16-1),0) | AS16: =IF(AM16=1,$AG16/(1+($AF$104+0.0001)/2)^(AN16-1),0) | AT16: =IF(AM16=1,$AG16/(1+($AF$104-0.0001)/2)^(AN16-1),0) | AU16: =IF(AM16=1,$AG16/(1+$AF$109/2)^(AN16-1),0) | AV16: =IF(AND($AG16>0,AF16>$AF$6,AF16<=$AF$7),$AG16*(1+$AF$9*($AF$7-AF16)/365),0) | AW16: =IF(AM16=1,$AG16/(1+($AF$8+$AF$10/10000)/2)^(AN16-1),0) | AX16: =IF(AM16=1,$AG16/(1+($AF$8+메인!$A$96/10000)/2)^(AN16-1),0) | AY16: =IF(AM16=1,$AG16/(1+($AF$8+메인!$A$97/10000)/2)^(AN16-1),0) | AZ16: =IF(AM16=1,$AG16/(1+($AF$8+메인!$A$98/10000)/2)^(AN16-1),0) | BA16: =IF(AM16=1,$AG16/(1+($AF$8+메인!$A$99/10000)/2)^(AN16-1),0) | BB16: =IF(AM16=1,$AG16/(1+($AF$8+메인!$A$100/10000)/2)^(AN16-1),0) | BC16: =IF(AM16=1,$AG16/(1+($AF$8+메인!$A$101/10000)/2)^(AN16-1),0) | BD16: =IF(AM16=1,$AG16/(1+($AF$8+메인!$A$102/10000)/2)^(AN16-1),0) | BE16: =IF(AM16=1,$AG16/(1+($AF$8+메인!$A$103/10000)/2)^(AN16-1),0) | BF16: =IF(AM16=1,$AG16/(1+($AF$8+메인!$A$104/10000)/2)^(AN16-1),0)
A17: 3 | B17: =EDATE($B$2,-6*(62-$A17)) | C17: =IF(AND(B17>$B$3,B17<=$B$2),IF(B17=$B$2,$B$5+100,$B$5),0) | D17: =IF(AND($C17>0,B17>$B$6),1,0) | E17: =IF(D17=1,SUM($D$15:D17),"") | F17: =IF(D17=1,$C17/(1+$B$8/2)^(E17-1),0) | G17: =IF(D17=1,$C17/(1+($B$8+0.0001)/2)^(E17-1),0) | H17: =IF(D17=1,$C17/(1+($B$8-0.0001)/2)^(E17-1),0) | I17: =IF(AND($C17>0,B17>$B$7),1,0) | J17: =IF(I17=1,SUM($I$15:I17),"") | K17: =IF(I17=1,$C17/(1+$B$99/2)^(J17-1),0) | L17: =IF(I17=1,$C17/(1+($B$99+0.0001)/2)^(J17-1),0) | M17: =IF(I17=1,$C17/(1+($B$99-0.0001)/2)^(J17-1),0) | N17: =IF(I17=1,$C17/(1+$B$104/2)^(J17-1),0) | O17: =IF(I17=1,$C17/(1+($B$104+0.0001)/2)^(J17-1),0) | P17: =IF(I17=1,$C17/(1+($B$104-0.0001)/2)^(J17-1),0) | Q17: =IF(I17=1,$C17/(1+$B$109/2)^(J17-1),0) | R17: =IF(AND($C17>0,B17>$B$6,B17<=$B$7),$C17*(1+$B$9*($B$7-B17)/365),0) | S17: =IF(I17=1,$C17/(1+($B$8+$B$10/10000)/2)^(J17-1),0) | T17: =IF(I17=1,$C17/(1+($B$8+메인!$A$96/10000)/2)^(J17-1),0) | U17: =IF(I17=1,$C17/(1+($B$8+메인!$A$97/10000)/2)^(J17-1),0) | V17: =IF(I17=1,$C17/(1+($B$8+메인!$A$98/10000)/2)^(J17-1),0) | W17: =IF(I17=1,$C17/(1+($B$8+메인!$A$99/10000)/2)^(J17-1),0) | X17: =IF(I17=1,$C17/(1+($B$8+메인!$A$100/10000)/2)^(J17-1),0) | Y17: =IF(I17=1,$C17/(1+($B$8+메인!$A$101/10000)/2)^(J17-1),0) | Z17: =IF(I17=1,$C17/(1+($B$8+메인!$A$102/10000)/2)^(J17-1),0) | AA17: =IF(I17=1,$C17/(1+($B$8+메인!$A$103/10000)/2)^(J17-1),0) | AB17: =IF(I17=1,$C17/(1+($B$8+메인!$A$104/10000)/2)^(J17-1),0) | AE17: 3 | AF17: =EDATE($AF$2,-6*(62-$AE17)) | AG17: =IF(AND(AF17>$AF$3,AF17<=$AF$2),IF(AF17=$AF$2,$AF$5+100,$AF$5),0) | AH17: =IF(AND($AG17>0,AF17>$AF$6),1,0) | AI17: =IF(AH17=1,SUM($AH$15:AH17),"") | AJ17: =IF(AH17=1,$AG17/(1+$AF$8/2)^(AI17-1),0) | AK17: =IF(AH17=1,$AG17/(1+($AF$8+0.0001)/2)^(AI17-1),0) | AL17: =IF(AH17=1,$AG17/(1+($AF$8-0.0001)/2)^(AI17-1),0) | AM17: =IF(AND($AG17>0,AF17>$AF$7),1,0) | AN17: =IF(AM17=1,SUM($AM$15:AM17),"") | AO17: =IF(AM17=1,$AG17/(1+$AF$99/2)^(AN17-1),0) | AP17: =IF(AM17=1,$AG17/(1+($AF$99+0.0001)/2)^(AN17-1),0) | AQ17: =IF(AM17=1,$AG17/(1+($AF$99-0.0001)/2)^(AN17-1),0) | AR17: =IF(AM17=1,$AG17/(1+$AF$104/2)^(AN17-1),0) | AS17: =IF(AM17=1,$AG17/(1+($AF$104+0.0001)/2)^(AN17-1),0) | AT17: =IF(AM17=1,$AG17/(1+($AF$104-0.0001)/2)^(AN17-1),0) | AU17: =IF(AM17=1,$AG17/(1+$AF$109/2)^(AN17-1),0) | AV17: =IF(AND($AG17>0,AF17>$AF$6,AF17<=$AF$7),$AG17*(1+$AF$9*($AF$7-AF17)/365),0) | AW17: =IF(AM17=1,$AG17/(1+($AF$8+$AF$10/10000)/2)^(AN17-1),0) | AX17: =IF(AM17=1,$AG17/(1+($AF$8+메인!$A$96/10000)/2)^(AN17-1),0) | AY17: =IF(AM17=1,$AG17/(1+($AF$8+메인!$A$97/10000)/2)^(AN17-1),0) | AZ17: =IF(AM17=1,$AG17/(1+($AF$8+메인!$A$98/10000)/2)^(AN17-1),0) | BA17: =IF(AM17=1,$AG17/(1+($AF$8+메인!$A$99/10000)/2)^(AN17-1),0) | BB17: =IF(AM17=1,$AG17/(1+($AF$8+메인!$A$100/10000)/2)^(AN17-1),0) | BC17: =IF(AM17=1,$AG17/(1+($AF$8+메인!$A$101/10000)/2)^(AN17-1),0) | BD17: =IF(AM17=1,$AG17/(1+($AF$8+메인!$A$102/10000)/2)^(AN17-1),0) | BE17: =IF(AM17=1,$AG17/(1+($AF$8+메인!$A$103/10000)/2)^(AN17-1),0) | BF17: =IF(AM17=1,$AG17/(1+($AF$8+메인!$A$104/10000)/2)^(AN17-1),0)
A18: 4 | B18: =EDATE($B$2,-6*(62-$A18)) | C18: =IF(AND(B18>$B$3,B18<=$B$2),IF(B18=$B$2,$B$5+100,$B$5),0) | D18: =IF(AND($C18>0,B18>$B$6),1,0) | E18: =IF(D18=1,SUM($D$15:D18),"") | F18: =IF(D18=1,$C18/(1+$B$8/2)^(E18-1),0) | G18: =IF(D18=1,$C18/(1+($B$8+0.0001)/2)^(E18-1),0) | H18: =IF(D18=1,$C18/(1+($B$8-0.0001)/2)^(E18-1),0) | I18: =IF(AND($C18>0,B18>$B$7),1,0) | J18: =IF(I18=1,SUM($I$15:I18),"") | K18: =IF(I18=1,$C18/(1+$B$99/2)^(J18-1),0) | L18: =IF(I18=1,$C18/(1+($B$99+0.0001)/2)^(J18-1),0) | M18: =IF(I18=1,$C18/(1+($B$99-0.0001)/2)^(J18-1),0) | N18: =IF(I18=1,$C18/(1+$B$104/2)^(J18-1),0) | O18: =IF(I18=1,$C18/(1+($B$104+0.0001)/2)^(J18-1),0) | P18: =IF(I18=1,$C18/(1+($B$104-0.0001)/2)^(J18-1),0) | Q18: =IF(I18=1,$C18/(1+$B$109/2)^(J18-1),0) | R18: =IF(AND($C18>0,B18>$B$6,B18<=$B$7),$C18*(1+$B$9*($B$7-B18)/365),0) | S18: =IF(I18=1,$C18/(1+($B$8+$B$10/10000)/2)^(J18-1),0) | T18: =IF(I18=1,$C18/(1+($B$8+메인!$A$96/10000)/2)^(J18-1),0) | U18: =IF(I18=1,$C18/(1+($B$8+메인!$A$97/10000)/2)^(J18-1),0) | V18: =IF(I18=1,$C18/(1+($B$8+메인!$A$98/10000)/2)^(J18-1),0) | W18: =IF(I18=1,$C18/(1+($B$8+메인!$A$99/10000)/2)^(J18-1),0) | X18: =IF(I18=1,$C18/(1+($B$8+메인!$A$100/10000)/2)^(J18-1),0) | Y18: =IF(I18=1,$C18/(1+($B$8+메인!$A$101/10000)/2)^(J18-1),0) | Z18: =IF(I18=1,$C18/(1+($B$8+메인!$A$102/10000)/2)^(J18-1),0) | AA18: =IF(I18=1,$C18/(1+($B$8+메인!$A$103/10000)/2)^(J18-1),0) | AB18: =IF(I18=1,$C18/(1+($B$8+메인!$A$104/10000)/2)^(J18-1),0) | AE18: 4 | AF18: =EDATE($AF$2,-6*(62-$AE18)) | AG18: =IF(AND(AF18>$AF$3,AF18<=$AF$2),IF(AF18=$AF$2,$AF$5+100,$AF$5),0) | AH18: =IF(AND($AG18>0,AF18>$AF$6),1,0) | AI18: =IF(AH18=1,SUM($AH$15:AH18),"") | AJ18: =IF(AH18=1,$AG18/(1+$AF$8/2)^(AI18-1),0) | AK18: =IF(AH18=1,$AG18/(1+($AF$8+0.0001)/2)^(AI18-1),0) | AL18: =IF(AH18=1,$AG18/(1+($AF$8-0.0001)/2)^(AI18-1),0) | AM18: =IF(AND($AG18>0,AF18>$AF$7),1,0) | AN18: =IF(AM18=1,SUM($AM$15:AM18),"") | AO18: =IF(AM18=1,$AG18/(1+$AF$99/2)^(AN18-1),0) | AP18: =IF(AM18=1,$AG18/(1+($AF$99+0.0001)/2)^(AN18-1),0) | AQ18: =IF(AM18=1,$AG18/(1+($AF$99-0.0001)/2)^(AN18-1),0) | AR18: =IF(AM18=1,$AG18/(1+$AF$104/2)^(AN18-1),0) | AS18: =IF(AM18=1,$AG18/(1+($AF$104+0.0001)/2)^(AN18-1),0) | AT18: =IF(AM18=1,$AG18/(1+($AF$104-0.0001)/2)^(AN18-1),0) | AU18: =IF(AM18=1,$AG18/(1+$AF$109/2)^(AN18-1),0) | AV18: =IF(AND($AG18>0,AF18>$AF$6,AF18<=$AF$7),$AG18*(1+$AF$9*($AF$7-AF18)/365),0) | AW18: =IF(AM18=1,$AG18/(1+($AF$8+$AF$10/10000)/2)^(AN18-1),0) | AX18: =IF(AM18=1,$AG18/(1+($AF$8+메인!$A$96/10000)/2)^(AN18-1),0) | AY18: =IF(AM18=1,$AG18/(1+($AF$8+메인!$A$97/10000)/2)^(AN18-1),0) | AZ18: =IF(AM18=1,$AG18/(1+($AF$8+메인!$A$98/10000)/2)^(AN18-1),0) | BA18: =IF(AM18=1,$AG18/(1+($AF$8+메인!$A$99/10000)/2)^(AN18-1),0) | BB18: =IF(AM18=1,$AG18/(1+($AF$8+메인!$A$100/10000)/2)^(AN18-1),0) | BC18: =IF(AM18=1,$AG18/(1+($AF$8+메인!$A$101/10000)/2)^(AN18-1),0) | BD18: =IF(AM18=1,$AG18/(1+($AF$8+메인!$A$102/10000)/2)^(AN18-1),0) | BE18: =IF(AM18=1,$AG18/(1+($AF$8+메인!$A$103/10000)/2)^(AN18-1),0) | BF18: =IF(AM18=1,$AG18/(1+($AF$8+메인!$A$104/10000)/2)^(AN18-1),0)
A19: 5 | B19: =EDATE($B$2,-6*(62-$A19)) | C19: =IF(AND(B19>$B$3,B19<=$B$2),IF(B19=$B$2,$B$5+100,$B$5),0) | D19: =IF(AND($C19>0,B19>$B$6),1,0) | E19: =IF(D19=1,SUM($D$15:D19),"") | F19: =IF(D19=1,$C19/(1+$B$8/2)^(E19-1),0) | G19: =IF(D19=1,$C19/(1+($B$8+0.0001)/2)^(E19-1),0) | H19: =IF(D19=1,$C19/(1+($B$8-0.0001)/2)^(E19-1),0) | I19: =IF(AND($C19>0,B19>$B$7),1,0) | J19: =IF(I19=1,SUM($I$15:I19),"") | K19: =IF(I19=1,$C19/(1+$B$99/2)^(J19-1),0) | L19: =IF(I19=1,$C19/(1+($B$99+0.0001)/2)^(J19-1),0) | M19: =IF(I19=1,$C19/(1+($B$99-0.0001)/2)^(J19-1),0) | N19: =IF(I19=1,$C19/(1+$B$104/2)^(J19-1),0) | O19: =IF(I19=1,$C19/(1+($B$104+0.0001)/2)^(J19-1),0) | P19: =IF(I19=1,$C19/(1+($B$104-0.0001)/2)^(J19-1),0) | Q19: =IF(I19=1,$C19/(1+$B$109/2)^(J19-1),0) | R19: =IF(AND($C19>0,B19>$B$6,B19<=$B$7),$C19*(1+$B$9*($B$7-B19)/365),0) | S19: =IF(I19=1,$C19/(1+($B$8+$B$10/10000)/2)^(J19-1),0) | T19: =IF(I19=1,$C19/(1+($B$8+메인!$A$96/10000)/2)^(J19-1),0) | U19: =IF(I19=1,$C19/(1+($B$8+메인!$A$97/10000)/2)^(J19-1),0) | V19: =IF(I19=1,$C19/(1+($B$8+메인!$A$98/10000)/2)^(J19-1),0) | W19: =IF(I19=1,$C19/(1+($B$8+메인!$A$99/10000)/2)^(J19-1),0) | X19: =IF(I19=1,$C19/(1+($B$8+메인!$A$100/10000)/2)^(J19-1),0) | Y19: =IF(I19=1,$C19/(1+($B$8+메인!$A$101/10000)/2)^(J19-1),0) | Z19: =IF(I19=1,$C19/(1+($B$8+메인!$A$102/10000)/2)^(J19-1),0) | AA19: =IF(I19=1,$C19/(1+($B$8+메인!$A$103/10000)/2)^(J19-1),0) | AB19: =IF(I19=1,$C19/(1+($B$8+메인!$A$104/10000)/2)^(J19-1),0) | AE19: 5 | AF19: =EDATE($AF$2,-6*(62-$AE19)) | AG19: =IF(AND(AF19>$AF$3,AF19<=$AF$2),IF(AF19=$AF$2,$AF$5+100,$AF$5),0) | AH19: =IF(AND($AG19>0,AF19>$AF$6),1,0) | AI19: =IF(AH19=1,SUM($AH$15:AH19),"") | AJ19: =IF(AH19=1,$AG19/(1+$AF$8/2)^(AI19-1),0) | AK19: =IF(AH19=1,$AG19/(1+($AF$8+0.0001)/2)^(AI19-1),0) | AL19: =IF(AH19=1,$AG19/(1+($AF$8-0.0001)/2)^(AI19-1),0) | AM19: =IF(AND($AG19>0,AF19>$AF$7),1,0) | AN19: =IF(AM19=1,SUM($AM$15:AM19),"") | AO19: =IF(AM19=1,$AG19/(1+$AF$99/2)^(AN19-1),0) | AP19: =IF(AM19=1,$AG19/(1+($AF$99+0.0001)/2)^(AN19-1),0) | AQ19: =IF(AM19=1,$AG19/(1+($AF$99-0.0001)/2)^(AN19-1),0) | AR19: =IF(AM19=1,$AG19/(1+$AF$104/2)^(AN19-1),0) | AS19: =IF(AM19=1,$AG19/(1+($AF$104+0.0001)/2)^(AN19-1),0) | AT19: =IF(AM19=1,$AG19/(1+($AF$104-0.0001)/2)^(AN19-1),0) | AU19: =IF(AM19=1,$AG19/(1+$AF$109/2)^(AN19-1),0) | AV19: =IF(AND($AG19>0,AF19>$AF$6,AF19<=$AF$7),$AG19*(1+$AF$9*($AF$7-AF19)/365),0) | AW19: =IF(AM19=1,$AG19/(1+($AF$8+$AF$10/10000)/2)^(AN19-1),0) | AX19: =IF(AM19=1,$AG19/(1+($AF$8+메인!$A$96/10000)/2)^(AN19-1),0) | AY19: =IF(AM19=1,$AG19/(1+($AF$8+메인!$A$97/10000)/2)^(AN19-1),0) | AZ19: =IF(AM19=1,$AG19/(1+($AF$8+메인!$A$98/10000)/2)^(AN19-1),0) | BA19: =IF(AM19=1,$AG19/(1+($AF$8+메인!$A$99/10000)/2)^(AN19-1),0) | BB19: =IF(AM19=1,$AG19/(1+($AF$8+메인!$A$100/10000)/2)^(AN19-1),0) | BC19: =IF(AM19=1,$AG19/(1+($AF$8+메인!$A$101/10000)/2)^(AN19-1),0) | BD19: =IF(AM19=1,$AG19/(1+($AF$8+메인!$A$102/10000)/2)^(AN19-1),0) | BE19: =IF(AM19=1,$AG19/(1+($AF$8+메인!$A$103/10000)/2)^(AN19-1),0) | BF19: =IF(AM19=1,$AG19/(1+($AF$8+메인!$A$104/10000)/2)^(AN19-1),0)
A20: 6 | B20: =EDATE($B$2,-6*(62-$A20)) | C20: =IF(AND(B20>$B$3,B20<=$B$2),IF(B20=$B$2,$B$5+100,$B$5),0) | D20: =IF(AND($C20>0,B20>$B$6),1,0) | E20: =IF(D20=1,SUM($D$15:D20),"") | F20: =IF(D20=1,$C20/(1+$B$8/2)^(E20-1),0) | G20: =IF(D20=1,$C20/(1+($B$8+0.0001)/2)^(E20-1),0) | H20: =IF(D20=1,$C20/(1+($B$8-0.0001)/2)^(E20-1),0) | I20: =IF(AND($C20>0,B20>$B$7),1,0) | J20: =IF(I20=1,SUM($I$15:I20),"") | K20: =IF(I20=1,$C20/(1+$B$99/2)^(J20-1),0) | L20: =IF(I20=1,$C20/(1+($B$99+0.0001)/2)^(J20-1),0) | M20: =IF(I20=1,$C20/(1+($B$99-0.0001)/2)^(J20-1),0) | N20: =IF(I20=1,$C20/(1+$B$104/2)^(J20-1),0) | O20: =IF(I20=1,$C20/(1+($B$104+0.0001)/2)^(J20-1),0) | P20: =IF(I20=1,$C20/(1+($B$104-0.0001)/2)^(J20-1),0) | Q20: =IF(I20=1,$C20/(1+$B$109/2)^(J20-1),0) | R20: =IF(AND($C20>0,B20>$B$6,B20<=$B$7),$C20*(1+$B$9*($B$7-B20)/365),0) | S20: =IF(I20=1,$C20/(1+($B$8+$B$10/10000)/2)^(J20-1),0) | T20: =IF(I20=1,$C20/(1+($B$8+메인!$A$96/10000)/2)^(J20-1),0) | U20: =IF(I20=1,$C20/(1+($B$8+메인!$A$97/10000)/2)^(J20-1),0) | V20: =IF(I20=1,$C20/(1+($B$8+메인!$A$98/10000)/2)^(J20-1),0) | W20: =IF(I20=1,$C20/(1+($B$8+메인!$A$99/10000)/2)^(J20-1),0) | X20: =IF(I20=1,$C20/(1+($B$8+메인!$A$100/10000)/2)^(J20-1),0) | Y20: =IF(I20=1,$C20/(1+($B$8+메인!$A$101/10000)/2)^(J20-1),0) | Z20: =IF(I20=1,$C20/(1+($B$8+메인!$A$102/10000)/2)^(J20-1),0) | AA20: =IF(I20=1,$C20/(1+($B$8+메인!$A$103/10000)/2)^(J20-1),0) | AB20: =IF(I20=1,$C20/(1+($B$8+메인!$A$104/10000)/2)^(J20-1),0) | AE20: 6 | AF20: =EDATE($AF$2,-6*(62-$AE20)) | AG20: =IF(AND(AF20>$AF$3,AF20<=$AF$2),IF(AF20=$AF$2,$AF$5+100,$AF$5),0) | AH20: =IF(AND($AG20>0,AF20>$AF$6),1,0) | AI20: =IF(AH20=1,SUM($AH$15:AH20),"") | AJ20: =IF(AH20=1,$AG20/(1+$AF$8/2)^(AI20-1),0) | AK20: =IF(AH20=1,$AG20/(1+($AF$8+0.0001)/2)^(AI20-1),0) | AL20: =IF(AH20=1,$AG20/(1+($AF$8-0.0001)/2)^(AI20-1),0) | AM20: =IF(AND($AG20>0,AF20>$AF$7),1,0) | AN20: =IF(AM20=1,SUM($AM$15:AM20),"") | AO20: =IF(AM20=1,$AG20/(1+$AF$99/2)^(AN20-1),0) | AP20: =IF(AM20=1,$AG20/(1+($AF$99+0.0001)/2)^(AN20-1),0) | AQ20: =IF(AM20=1,$AG20/(1+($AF$99-0.0001)/2)^(AN20-1),0) | AR20: =IF(AM20=1,$AG20/(1+$AF$104/2)^(AN20-1),0) | AS20: =IF(AM20=1,$AG20/(1+($AF$104+0.0001)/2)^(AN20-1),0) | AT20: =IF(AM20=1,$AG20/(1+($AF$104-0.0001)/2)^(AN20-1),0) | AU20: =IF(AM20=1,$AG20/(1+$AF$109/2)^(AN20-1),0) | AV20: =IF(AND($AG20>0,AF20>$AF$6,AF20<=$AF$7),$AG20*(1+$AF$9*($AF$7-AF20)/365),0) | AW20: =IF(AM20=1,$AG20/(1+($AF$8+$AF$10/10000)/2)^(AN20-1),0) | AX20: =IF(AM20=1,$AG20/(1+($AF$8+메인!$A$96/10000)/2)^(AN20-1),0) | AY20: =IF(AM20=1,$AG20/(1+($AF$8+메인!$A$97/10000)/2)^(AN20-1),0) | AZ20: =IF(AM20=1,$AG20/(1+($AF$8+메인!$A$98/10000)/2)^(AN20-1),0) | BA20: =IF(AM20=1,$AG20/(1+($AF$8+메인!$A$99/10000)/2)^(AN20-1),0) | BB20: =IF(AM20=1,$AG20/(1+($AF$8+메인!$A$100/10000)/2)^(AN20-1),0) | BC20: =IF(AM20=1,$AG20/(1+($AF$8+메인!$A$101/10000)/2)^(AN20-1),0) | BD20: =IF(AM20=1,$AG20/(1+($AF$8+메인!$A$102/10000)/2)^(AN20-1),0) | BE20: =IF(AM20=1,$AG20/(1+($AF$8+메인!$A$103/10000)/2)^(AN20-1),0) | BF20: =IF(AM20=1,$AG20/(1+($AF$8+메인!$A$104/10000)/2)^(AN20-1),0)
A21: 7 | B21: =EDATE($B$2,-6*(62-$A21)) | C21: =IF(AND(B21>$B$3,B21<=$B$2),IF(B21=$B$2,$B$5+100,$B$5),0) | D21: =IF(AND($C21>0,B21>$B$6),1,0) | E21: =IF(D21=1,SUM($D$15:D21),"") | F21: =IF(D21=1,$C21/(1+$B$8/2)^(E21-1),0) | G21: =IF(D21=1,$C21/(1+($B$8+0.0001)/2)^(E21-1),0) | H21: =IF(D21=1,$C21/(1+($B$8-0.0001)/2)^(E21-1),0) | I21: =IF(AND($C21>0,B21>$B$7),1,0) | J21: =IF(I21=1,SUM($I$15:I21),"") | K21: =IF(I21=1,$C21/(1+$B$99/2)^(J21-1),0) | L21: =IF(I21=1,$C21/(1+($B$99+0.0001)/2)^(J21-1),0) | M21: =IF(I21=1,$C21/(1+($B$99-0.0001)/2)^(J21-1),0) | N21: =IF(I21=1,$C21/(1+$B$104/2)^(J21-1),0) | O21: =IF(I21=1,$C21/(1+($B$104+0.0001)/2)^(J21-1),0) | P21: =IF(I21=1,$C21/(1+($B$104-0.0001)/2)^(J21-1),0) | Q21: =IF(I21=1,$C21/(1+$B$109/2)^(J21-1),0) | R21: =IF(AND($C21>0,B21>$B$6,B21<=$B$7),$C21*(1+$B$9*($B$7-B21)/365),0) | S21: =IF(I21=1,$C21/(1+($B$8+$B$10/10000)/2)^(J21-1),0) | T21: =IF(I21=1,$C21/(1+($B$8+메인!$A$96/10000)/2)^(J21-1),0) | U21: =IF(I21=1,$C21/(1+($B$8+메인!$A$97/10000)/2)^(J21-1),0) | V21: =IF(I21=1,$C21/(1+($B$8+메인!$A$98/10000)/2)^(J21-1),0) | W21: =IF(I21=1,$C21/(1+($B$8+메인!$A$99/10000)/2)^(J21-1),0) | X21: =IF(I21=1,$C21/(1+($B$8+메인!$A$100/10000)/2)^(J21-1),0) | Y21: =IF(I21=1,$C21/(1+($B$8+메인!$A$101/10000)/2)^(J21-1),0) | Z21: =IF(I21=1,$C21/(1+($B$8+메인!$A$102/10000)/2)^(J21-1),0) | AA21: =IF(I21=1,$C21/(1+($B$8+메인!$A$103/10000)/2)^(J21-1),0) | AB21: =IF(I21=1,$C21/(1+($B$8+메인!$A$104/10000)/2)^(J21-1),0) | AE21: 7 | AF21: =EDATE($AF$2,-6*(62-$AE21)) | AG21: =IF(AND(AF21>$AF$3,AF21<=$AF$2),IF(AF21=$AF$2,$AF$5+100,$AF$5),0) | AH21: =IF(AND($AG21>0,AF21>$AF$6),1,0) | AI21: =IF(AH21=1,SUM($AH$15:AH21),"") | AJ21: =IF(AH21=1,$AG21/(1+$AF$8/2)^(AI21-1),0) | AK21: =IF(AH21=1,$AG21/(1+($AF$8+0.0001)/2)^(AI21-1),0) | AL21: =IF(AH21=1,$AG21/(1+($AF$8-0.0001)/2)^(AI21-1),0) | AM21: =IF(AND($AG21>0,AF21>$AF$7),1,0) | AN21: =IF(AM21=1,SUM($AM$15:AM21),"") | AO21: =IF(AM21=1,$AG21/(1+$AF$99/2)^(AN21-1),0) | AP21: =IF(AM21=1,$AG21/(1+($AF$99+0.0001)/2)^(AN21-1),0) | AQ21: =IF(AM21=1,$AG21/(1+($AF$99-0.0001)/2)^(AN21-1),0) | AR21: =IF(AM21=1,$AG21/(1+$AF$104/2)^(AN21-1),0) | AS21: =IF(AM21=1,$AG21/(1+($AF$104+0.0001)/2)^(AN21-1),0) | AT21: =IF(AM21=1,$AG21/(1+($AF$104-0.0001)/2)^(AN21-1),0) | AU21: =IF(AM21=1,$AG21/(1+$AF$109/2)^(AN21-1),0) | AV21: =IF(AND($AG21>0,AF21>$AF$6,AF21<=$AF$7),$AG21*(1+$AF$9*($AF$7-AF21)/365),0) | AW21: =IF(AM21=1,$AG21/(1+($AF$8+$AF$10/10000)/2)^(AN21-1),0) | AX21: =IF(AM21=1,$AG21/(1+($AF$8+메인!$A$96/10000)/2)^(AN21-1),0) | AY21: =IF(AM21=1,$AG21/(1+($AF$8+메인!$A$97/10000)/2)^(AN21-1),0) | AZ21: =IF(AM21=1,$AG21/(1+($AF$8+메인!$A$98/10000)/2)^(AN21-1),0) | BA21: =IF(AM21=1,$AG21/(1+($AF$8+메인!$A$99/10000)/2)^(AN21-1),0) | BB21: =IF(AM21=1,$AG21/(1+($AF$8+메인!$A$100/10000)/2)^(AN21-1),0) | BC21: =IF(AM21=1,$AG21/(1+($AF$8+메인!$A$101/10000)/2)^(AN21-1),0) | BD21: =IF(AM21=1,$AG21/(1+($AF$8+메인!$A$102/10000)/2)^(AN21-1),0) | BE21: =IF(AM21=1,$AG21/(1+($AF$8+메인!$A$103/10000)/2)^(AN21-1),0) | BF21: =IF(AM21=1,$AG21/(1+($AF$8+메인!$A$104/10000)/2)^(AN21-1),0)
A22: 8 | B22: =EDATE($B$2,-6*(62-$A22)) | C22: =IF(AND(B22>$B$3,B22<=$B$2),IF(B22=$B$2,$B$5+100,$B$5),0) | D22: =IF(AND($C22>0,B22>$B$6),1,0) | E22: =IF(D22=1,SUM($D$15:D22),"") | F22: =IF(D22=1,$C22/(1+$B$8/2)^(E22-1),0) | G22: =IF(D22=1,$C22/(1+($B$8+0.0001)/2)^(E22-1),0) | H22: =IF(D22=1,$C22/(1+($B$8-0.0001)/2)^(E22-1),0) | I22: =IF(AND($C22>0,B22>$B$7),1,0) | J22: =IF(I22=1,SUM($I$15:I22),"") | K22: =IF(I22=1,$C22/(1+$B$99/2)^(J22-1),0) | L22: =IF(I22=1,$C22/(1+($B$99+0.0001)/2)^(J22-1),0) | M22: =IF(I22=1,$C22/(1+($B$99-0.0001)/2)^(J22-1),0) | N22: =IF(I22=1,$C22/(1+$B$104/2)^(J22-1),0) | O22: =IF(I22=1,$C22/(1+($B$104+0.0001)/2)^(J22-1),0) | P22: =IF(I22=1,$C22/(1+($B$104-0.0001)/2)^(J22-1),0) | Q22: =IF(I22=1,$C22/(1+$B$109/2)^(J22-1),0) | R22: =IF(AND($C22>0,B22>$B$6,B22<=$B$7),$C22*(1+$B$9*($B$7-B22)/365),0) | S22: =IF(I22=1,$C22/(1+($B$8+$B$10/10000)/2)^(J22-1),0) | T22: =IF(I22=1,$C22/(1+($B$8+메인!$A$96/10000)/2)^(J22-1),0) | U22: =IF(I22=1,$C22/(1+($B$8+메인!$A$97/10000)/2)^(J22-1),0) | V22: =IF(I22=1,$C22/(1+($B$8+메인!$A$98/10000)/2)^(J22-1),0) | W22: =IF(I22=1,$C22/(1+($B$8+메인!$A$99/10000)/2)^(J22-1),0) | X22: =IF(I22=1,$C22/(1+($B$8+메인!$A$100/10000)/2)^(J22-1),0) | Y22: =IF(I22=1,$C22/(1+($B$8+메인!$A$101/10000)/2)^(J22-1),0) | Z22: =IF(I22=1,$C22/(1+($B$8+메인!$A$102/10000)/2)^(J22-1),0) | AA22: =IF(I22=1,$C22/(1+($B$8+메인!$A$103/10000)/2)^(J22-1),0) | AB22: =IF(I22=1,$C22/(1+($B$8+메인!$A$104/10000)/2)^(J22-1),0) | AE22: 8 | AF22: =EDATE($AF$2,-6*(62-$AE22)) | AG22: =IF(AND(AF22>$AF$3,AF22<=$AF$2),IF(AF22=$AF$2,$AF$5+100,$AF$5),0) | AH22: =IF(AND($AG22>0,AF22>$AF$6),1,0) | AI22: =IF(AH22=1,SUM($AH$15:AH22),"") | AJ22: =IF(AH22=1,$AG22/(1+$AF$8/2)^(AI22-1),0) | AK22: =IF(AH22=1,$AG22/(1+($AF$8+0.0001)/2)^(AI22-1),0) | AL22: =IF(AH22=1,$AG22/(1+($AF$8-0.0001)/2)^(AI22-1),0) | AM22: =IF(AND($AG22>0,AF22>$AF$7),1,0) | AN22: =IF(AM22=1,SUM($AM$15:AM22),"") | AO22: =IF(AM22=1,$AG22/(1+$AF$99/2)^(AN22-1),0) | AP22: =IF(AM22=1,$AG22/(1+($AF$99+0.0001)/2)^(AN22-1),0) | AQ22: =IF(AM22=1,$AG22/(1+($AF$99-0.0001)/2)^(AN22-1),0) | AR22: =IF(AM22=1,$AG22/(1+$AF$104/2)^(AN22-1),0) | AS22: =IF(AM22=1,$AG22/(1+($AF$104+0.0001)/2)^(AN22-1),0) | AT22: =IF(AM22=1,$AG22/(1+($AF$104-0.0001)/2)^(AN22-1),0) | AU22: =IF(AM22=1,$AG22/(1+$AF$109/2)^(AN22-1),0) | AV22: =IF(AND($AG22>0,AF22>$AF$6,AF22<=$AF$7),$AG22*(1+$AF$9*($AF$7-AF22)/365),0) | AW22: =IF(AM22=1,$AG22/(1+($AF$8+$AF$10/10000)/2)^(AN22-1),0) | AX22: =IF(AM22=1,$AG22/(1+($AF$8+메인!$A$96/10000)/2)^(AN22-1),0) | AY22: =IF(AM22=1,$AG22/(1+($AF$8+메인!$A$97/10000)/2)^(AN22-1),0) | AZ22: =IF(AM22=1,$AG22/(1+($AF$8+메인!$A$98/10000)/2)^(AN22-1),0) | BA22: =IF(AM22=1,$AG22/(1+($AF$8+메인!$A$99/10000)/2)^(AN22-1),0) | BB22: =IF(AM22=1,$AG22/(1+($AF$8+메인!$A$100/10000)/2)^(AN22-1),0) | BC22: =IF(AM22=1,$AG22/(1+($AF$8+메인!$A$101/10000)/2)^(AN22-1),0) | BD22: =IF(AM22=1,$AG22/(1+($AF$8+메인!$A$102/10000)/2)^(AN22-1),0) | BE22: =IF(AM22=1,$AG22/(1+($AF$8+메인!$A$103/10000)/2)^(AN22-1),0) | BF22: =IF(AM22=1,$AG22/(1+($AF$8+메인!$A$104/10000)/2)^(AN22-1),0)
A23: 9 | B23: =EDATE($B$2,-6*(62-$A23)) | C23: =IF(AND(B23>$B$3,B23<=$B$2),IF(B23=$B$2,$B$5+100,$B$5),0) | D23: =IF(AND($C23>0,B23>$B$6),1,0) | E23: =IF(D23=1,SUM($D$15:D23),"") | F23: =IF(D23=1,$C23/(1+$B$8/2)^(E23-1),0) | G23: =IF(D23=1,$C23/(1+($B$8+0.0001)/2)^(E23-1),0) | H23: =IF(D23=1,$C23/(1+($B$8-0.0001)/2)^(E23-1),0) | I23: =IF(AND($C23>0,B23>$B$7),1,0) | J23: =IF(I23=1,SUM($I$15:I23),"") | K23: =IF(I23=1,$C23/(1+$B$99/2)^(J23-1),0) | L23: =IF(I23=1,$C23/(1+($B$99+0.0001)/2)^(J23-1),0) | M23: =IF(I23=1,$C23/(1+($B$99-0.0001)/2)^(J23-1),0) | N23: =IF(I23=1,$C23/(1+$B$104/2)^(J23-1),0) | O23: =IF(I23=1,$C23/(1+($B$104+0.0001)/2)^(J23-1),0) | P23: =IF(I23=1,$C23/(1+($B$104-0.0001)/2)^(J23-1),0) | Q23: =IF(I23=1,$C23/(1+$B$109/2)^(J23-1),0) | R23: =IF(AND($C23>0,B23>$B$6,B23<=$B$7),$C23*(1+$B$9*($B$7-B23)/365),0) | S23: =IF(I23=1,$C23/(1+($B$8+$B$10/10000)/2)^(J23-1),0) | T23: =IF(I23=1,$C23/(1+($B$8+메인!$A$96/10000)/2)^(J23-1),0) | U23: =IF(I23=1,$C23/(1+($B$8+메인!$A$97/10000)/2)^(J23-1),0) | V23: =IF(I23=1,$C23/(1+($B$8+메인!$A$98/10000)/2)^(J23-1),0) | W23: =IF(I23=1,$C23/(1+($B$8+메인!$A$99/10000)/2)^(J23-1),0) | X23: =IF(I23=1,$C23/(1+($B$8+메인!$A$100/10000)/2)^(J23-1),0) | Y23: =IF(I23=1,$C23/(1+($B$8+메인!$A$101/10000)/2)^(J23-1),0) | Z23: =IF(I23=1,$C23/(1+($B$8+메인!$A$102/10000)/2)^(J23-1),0) | AA23: =IF(I23=1,$C23/(1+($B$8+메인!$A$103/10000)/2)^(J23-1),0) | AB23: =IF(I23=1,$C23/(1+($B$8+메인!$A$104/10000)/2)^(J23-1),0) | AE23: 9 | AF23: =EDATE($AF$2,-6*(62-$AE23)) | AG23: =IF(AND(AF23>$AF$3,AF23<=$AF$2),IF(AF23=$AF$2,$AF$5+100,$AF$5),0) | AH23: =IF(AND($AG23>0,AF23>$AF$6),1,0) | AI23: =IF(AH23=1,SUM($AH$15:AH23),"") | AJ23: =IF(AH23=1,$AG23/(1+$AF$8/2)^(AI23-1),0) | AK23: =IF(AH23=1,$AG23/(1+($AF$8+0.0001)/2)^(AI23-1),0) | AL23: =IF(AH23=1,$AG23/(1+($AF$8-0.0001)/2)^(AI23-1),0) | AM23: =IF(AND($AG23>0,AF23>$AF$7),1,0) | AN23: =IF(AM23=1,SUM($AM$15:AM23),"") | AO23: =IF(AM23=1,$AG23/(1+$AF$99/2)^(AN23-1),0) | AP23: =IF(AM23=1,$AG23/(1+($AF$99+0.0001)/2)^(AN23-1),0) | AQ23: =IF(AM23=1,$AG23/(1+($AF$99-0.0001)/2)^(AN23-1),0) | AR23: =IF(AM23=1,$AG23/(1+$AF$104/2)^(AN23-1),0) | AS23: =IF(AM23=1,$AG23/(1+($AF$104+0.0001)/2)^(AN23-1),0) | AT23: =IF(AM23=1,$AG23/(1+($AF$104-0.0001)/2)^(AN23-1),0) | AU23: =IF(AM23=1,$AG23/(1+$AF$109/2)^(AN23-1),0) | AV23: =IF(AND($AG23>0,AF23>$AF$6,AF23<=$AF$7),$AG23*(1+$AF$9*($AF$7-AF23)/365),0) | AW23: =IF(AM23=1,$AG23/(1+($AF$8+$AF$10/10000)/2)^(AN23-1),0) | AX23: =IF(AM23=1,$AG23/(1+($AF$8+메인!$A$96/10000)/2)^(AN23-1),0) | AY23: =IF(AM23=1,$AG23/(1+($AF$8+메인!$A$97/10000)/2)^(AN23-1),0) | AZ23: =IF(AM23=1,$AG23/(1+($AF$8+메인!$A$98/10000)/2)^(AN23-1),0) | BA23: =IF(AM23=1,$AG23/(1+($AF$8+메인!$A$99/10000)/2)^(AN23-1),0) | BB23: =IF(AM23=1,$AG23/(1+($AF$8+메인!$A$100/10000)/2)^(AN23-1),0) | BC23: =IF(AM23=1,$AG23/(1+($AF$8+메인!$A$101/10000)/2)^(AN23-1),0) | BD23: =IF(AM23=1,$AG23/(1+($AF$8+메인!$A$102/10000)/2)^(AN23-1),0) | BE23: =IF(AM23=1,$AG23/(1+($AF$8+메인!$A$103/10000)/2)^(AN23-1),0) | BF23: =IF(AM23=1,$AG23/(1+($AF$8+메인!$A$104/10000)/2)^(AN23-1),0)
A24: 10 | B24: =EDATE($B$2,-6*(62-$A24)) | C24: =IF(AND(B24>$B$3,B24<=$B$2),IF(B24=$B$2,$B$5+100,$B$5),0) | D24: =IF(AND($C24>0,B24>$B$6),1,0) | E24: =IF(D24=1,SUM($D$15:D24),"") | F24: =IF(D24=1,$C24/(1+$B$8/2)^(E24-1),0) | G24: =IF(D24=1,$C24/(1+($B$8+0.0001)/2)^(E24-1),0) | H24: =IF(D24=1,$C24/(1+($B$8-0.0001)/2)^(E24-1),0) | I24: =IF(AND($C24>0,B24>$B$7),1,0) | J24: =IF(I24=1,SUM($I$15:I24),"") | K24: =IF(I24=1,$C24/(1+$B$99/2)^(J24-1),0) | L24: =IF(I24=1,$C24/(1+($B$99+0.0001)/2)^(J24-1),0) | M24: =IF(I24=1,$C24/(1+($B$99-0.0001)/2)^(J24-1),0) | N24: =IF(I24=1,$C24/(1+$B$104/2)^(J24-1),0) | O24: =IF(I24=1,$C24/(1+($B$104+0.0001)/2)^(J24-1),0) | P24: =IF(I24=1,$C24/(1+($B$104-0.0001)/2)^(J24-1),0) | Q24: =IF(I24=1,$C24/(1+$B$109/2)^(J24-1),0) | R24: =IF(AND($C24>0,B24>$B$6,B24<=$B$7),$C24*(1+$B$9*($B$7-B24)/365),0) | S24: =IF(I24=1,$C24/(1+($B$8+$B$10/10000)/2)^(J24-1),0) | T24: =IF(I24=1,$C24/(1+($B$8+메인!$A$96/10000)/2)^(J24-1),0) | U24: =IF(I24=1,$C24/(1+($B$8+메인!$A$97/10000)/2)^(J24-1),0) | V24: =IF(I24=1,$C24/(1+($B$8+메인!$A$98/10000)/2)^(J24-1),0) | W24: =IF(I24=1,$C24/(1+($B$8+메인!$A$99/10000)/2)^(J24-1),0) | X24: =IF(I24=1,$C24/(1+($B$8+메인!$A$100/10000)/2)^(J24-1),0) | Y24: =IF(I24=1,$C24/(1+($B$8+메인!$A$101/10000)/2)^(J24-1),0) | Z24: =IF(I24=1,$C24/(1+($B$8+메인!$A$102/10000)/2)^(J24-1),0) | AA24: =IF(I24=1,$C24/(1+($B$8+메인!$A$103/10000)/2)^(J24-1),0) | AB24: =IF(I24=1,$C24/(1+($B$8+메인!$A$104/10000)/2)^(J24-1),0) | AE24: 10 | AF24: =EDATE($AF$2,-6*(62-$AE24)) | AG24: =IF(AND(AF24>$AF$3,AF24<=$AF$2),IF(AF24=$AF$2,$AF$5+100,$AF$5),0) | AH24: =IF(AND($AG24>0,AF24>$AF$6),1,0) | AI24: =IF(AH24=1,SUM($AH$15:AH24),"") | AJ24: =IF(AH24=1,$AG24/(1+$AF$8/2)^(AI24-1),0) | AK24: =IF(AH24=1,$AG24/(1+($AF$8+0.0001)/2)^(AI24-1),0) | AL24: =IF(AH24=1,$AG24/(1+($AF$8-0.0001)/2)^(AI24-1),0) | AM24: =IF(AND($AG24>0,AF24>$AF$7),1,0) | AN24: =IF(AM24=1,SUM($AM$15:AM24),"") | AO24: =IF(AM24=1,$AG24/(1+$AF$99/2)^(AN24-1),0) | AP24: =IF(AM24=1,$AG24/(1+($AF$99+0.0001)/2)^(AN24-1),0) | AQ24: =IF(AM24=1,$AG24/(1+($AF$99-0.0001)/2)^(AN24-1),0) | AR24: =IF(AM24=1,$AG24/(1+$AF$104/2)^(AN24-1),0) | AS24: =IF(AM24=1,$AG24/(1+($AF$104+0.0001)/2)^(AN24-1),0) | AT24: =IF(AM24=1,$AG24/(1+($AF$104-0.0001)/2)^(AN24-1),0) | AU24: =IF(AM24=1,$AG24/(1+$AF$109/2)^(AN24-1),0) | AV24: =IF(AND($AG24>0,AF24>$AF$6,AF24<=$AF$7),$AG24*(1+$AF$9*($AF$7-AF24)/365),0) | AW24: =IF(AM24=1,$AG24/(1+($AF$8+$AF$10/10000)/2)^(AN24-1),0) | AX24: =IF(AM24=1,$AG24/(1+($AF$8+메인!$A$96/10000)/2)^(AN24-1),0) | AY24: =IF(AM24=1,$AG24/(1+($AF$8+메인!$A$97/10000)/2)^(AN24-1),0) | AZ24: =IF(AM24=1,$AG24/(1+($AF$8+메인!$A$98/10000)/2)^(AN24-1),0) | BA24: =IF(AM24=1,$AG24/(1+($AF$8+메인!$A$99/10000)/2)^(AN24-1),0) | BB24: =IF(AM24=1,$AG24/(1+($AF$8+메인!$A$100/10000)/2)^(AN24-1),0) | BC24: =IF(AM24=1,$AG24/(1+($AF$8+메인!$A$101/10000)/2)^(AN24-1),0) | BD24: =IF(AM24=1,$AG24/(1+($AF$8+메인!$A$102/10000)/2)^(AN24-1),0) | BE24: =IF(AM24=1,$AG24/(1+($AF$8+메인!$A$103/10000)/2)^(AN24-1),0) | BF24: =IF(AM24=1,$AG24/(1+($AF$8+메인!$A$104/10000)/2)^(AN24-1),0)
A25: 11 | B25: =EDATE($B$2,-6*(62-$A25)) | C25: =IF(AND(B25>$B$3,B25<=$B$2),IF(B25=$B$2,$B$5+100,$B$5),0) | D25: =IF(AND($C25>0,B25>$B$6),1,0) | E25: =IF(D25=1,SUM($D$15:D25),"") | F25: =IF(D25=1,$C25/(1+$B$8/2)^(E25-1),0) | G25: =IF(D25=1,$C25/(1+($B$8+0.0001)/2)^(E25-1),0) | H25: =IF(D25=1,$C25/(1+($B$8-0.0001)/2)^(E25-1),0) | I25: =IF(AND($C25>0,B25>$B$7),1,0) | J25: =IF(I25=1,SUM($I$15:I25),"") | K25: =IF(I25=1,$C25/(1+$B$99/2)^(J25-1),0) | L25: =IF(I25=1,$C25/(1+($B$99+0.0001)/2)^(J25-1),0) | M25: =IF(I25=1,$C25/(1+($B$99-0.0001)/2)^(J25-1),0) | N25: =IF(I25=1,$C25/(1+$B$104/2)^(J25-1),0) | O25: =IF(I25=1,$C25/(1+($B$104+0.0001)/2)^(J25-1),0) | P25: =IF(I25=1,$C25/(1+($B$104-0.0001)/2)^(J25-1),0) | Q25: =IF(I25=1,$C25/(1+$B$109/2)^(J25-1),0) | R25: =IF(AND($C25>0,B25>$B$6,B25<=$B$7),$C25*(1+$B$9*($B$7-B25)/365),0) | S25: =IF(I25=1,$C25/(1+($B$8+$B$10/10000)/2)^(J25-1),0) | T25: =IF(I25=1,$C25/(1+($B$8+메인!$A$96/10000)/2)^(J25-1),0) | U25: =IF(I25=1,$C25/(1+($B$8+메인!$A$97/10000)/2)^(J25-1),0) | V25: =IF(I25=1,$C25/(1+($B$8+메인!$A$98/10000)/2)^(J25-1),0) | W25: =IF(I25=1,$C25/(1+($B$8+메인!$A$99/10000)/2)^(J25-1),0) | X25: =IF(I25=1,$C25/(1+($B$8+메인!$A$100/10000)/2)^(J25-1),0) | Y25: =IF(I25=1,$C25/(1+($B$8+메인!$A$101/10000)/2)^(J25-1),0) | Z25: =IF(I25=1,$C25/(1+($B$8+메인!$A$102/10000)/2)^(J25-1),0) | AA25: =IF(I25=1,$C25/(1+($B$8+메인!$A$103/10000)/2)^(J25-1),0) | AB25: =IF(I25=1,$C25/(1+($B$8+메인!$A$104/10000)/2)^(J25-1),0) | AE25: 11 | AF25: =EDATE($AF$2,-6*(62-$AE25)) | AG25: =IF(AND(AF25>$AF$3,AF25<=$AF$2),IF(AF25=$AF$2,$AF$5+100,$AF$5),0) | AH25: =IF(AND($AG25>0,AF25>$AF$6),1,0) | AI25: =IF(AH25=1,SUM($AH$15:AH25),"") | AJ25: =IF(AH25=1,$AG25/(1+$AF$8/2)^(AI25-1),0) | AK25: =IF(AH25=1,$AG25/(1+($AF$8+0.0001)/2)^(AI25-1),0) | AL25: =IF(AH25=1,$AG25/(1+($AF$8-0.0001)/2)^(AI25-1),0) | AM25: =IF(AND($AG25>0,AF25>$AF$7),1,0) | AN25: =IF(AM25=1,SUM($AM$15:AM25),"") | AO25: =IF(AM25=1,$AG25/(1+$AF$99/2)^(AN25-1),0) | AP25: =IF(AM25=1,$AG25/(1+($AF$99+0.0001)/2)^(AN25-1),0) | AQ25: =IF(AM25=1,$AG25/(1+($AF$99-0.0001)/2)^(AN25-1),0) | AR25: =IF(AM25=1,$AG25/(1+$AF$104/2)^(AN25-1),0) | AS25: =IF(AM25=1,$AG25/(1+($AF$104+0.0001)/2)^(AN25-1),0) | AT25: =IF(AM25=1,$AG25/(1+($AF$104-0.0001)/2)^(AN25-1),0) | AU25: =IF(AM25=1,$AG25/(1+$AF$109/2)^(AN25-1),0) | AV25: =IF(AND($AG25>0,AF25>$AF$6,AF25<=$AF$7),$AG25*(1+$AF$9*($AF$7-AF25)/365),0) | AW25: =IF(AM25=1,$AG25/(1+($AF$8+$AF$10/10000)/2)^(AN25-1),0) | AX25: =IF(AM25=1,$AG25/(1+($AF$8+메인!$A$96/10000)/2)^(AN25-1),0) | AY25: =IF(AM25=1,$AG25/(1+($AF$8+메인!$A$97/10000)/2)^(AN25-1),0) | AZ25: =IF(AM25=1,$AG25/(1+($AF$8+메인!$A$98/10000)/2)^(AN25-1),0) | BA25: =IF(AM25=1,$AG25/(1+($AF$8+메인!$A$99/10000)/2)^(AN25-1),0) | BB25: =IF(AM25=1,$AG25/(1+($AF$8+메인!$A$100/10000)/2)^(AN25-1),0) | BC25: =IF(AM25=1,$AG25/(1+($AF$8+메인!$A$101/10000)/2)^(AN25-1),0) | BD25: =IF(AM25=1,$AG25/(1+($AF$8+메인!$A$102/10000)/2)^(AN25-1),0) | BE25: =IF(AM25=1,$AG25/(1+($AF$8+메인!$A$103/10000)/2)^(AN25-1),0) | BF25: =IF(AM25=1,$AG25/(1+($AF$8+메인!$A$104/10000)/2)^(AN25-1),0)
A26: 12 | B26: =EDATE($B$2,-6*(62-$A26)) | C26: =IF(AND(B26>$B$3,B26<=$B$2),IF(B26=$B$2,$B$5+100,$B$5),0) | D26: =IF(AND($C26>0,B26>$B$6),1,0) | E26: =IF(D26=1,SUM($D$15:D26),"") | F26: =IF(D26=1,$C26/(1+$B$8/2)^(E26-1),0) | G26: =IF(D26=1,$C26/(1+($B$8+0.0001)/2)^(E26-1),0) | H26: =IF(D26=1,$C26/(1+($B$8-0.0001)/2)^(E26-1),0) | I26: =IF(AND($C26>0,B26>$B$7),1,0) | J26: =IF(I26=1,SUM($I$15:I26),"") | K26: =IF(I26=1,$C26/(1+$B$99/2)^(J26-1),0) | L26: =IF(I26=1,$C26/(1+($B$99+0.0001)/2)^(J26-1),0) | M26: =IF(I26=1,$C26/(1+($B$99-0.0001)/2)^(J26-1),0) | N26: =IF(I26=1,$C26/(1+$B$104/2)^(J26-1),0) | O26: =IF(I26=1,$C26/(1+($B$104+0.0001)/2)^(J26-1),0) | P26: =IF(I26=1,$C26/(1+($B$104-0.0001)/2)^(J26-1),0) | Q26: =IF(I26=1,$C26/(1+$B$109/2)^(J26-1),0) | R26: =IF(AND($C26>0,B26>$B$6,B26<=$B$7),$C26*(1+$B$9*($B$7-B26)/365),0) | S26: =IF(I26=1,$C26/(1+($B$8+$B$10/10000)/2)^(J26-1),0) | T26: =IF(I26=1,$C26/(1+($B$8+메인!$A$96/10000)/2)^(J26-1),0) | U26: =IF(I26=1,$C26/(1+($B$8+메인!$A$97/10000)/2)^(J26-1),0) | V26: =IF(I26=1,$C26/(1+($B$8+메인!$A$98/10000)/2)^(J26-1),0) | W26: =IF(I26=1,$C26/(1+($B$8+메인!$A$99/10000)/2)^(J26-1),0) | X26: =IF(I26=1,$C26/(1+($B$8+메인!$A$100/10000)/2)^(J26-1),0) | Y26: =IF(I26=1,$C26/(1+($B$8+메인!$A$101/10000)/2)^(J26-1),0) | Z26: =IF(I26=1,$C26/(1+($B$8+메인!$A$102/10000)/2)^(J26-1),0) | AA26: =IF(I26=1,$C26/(1+($B$8+메인!$A$103/10000)/2)^(J26-1),0) | AB26: =IF(I26=1,$C26/(1+($B$8+메인!$A$104/10000)/2)^(J26-1),0) | AE26: 12 | AF26: =EDATE($AF$2,-6*(62-$AE26)) | AG26: =IF(AND(AF26>$AF$3,AF26<=$AF$2),IF(AF26=$AF$2,$AF$5+100,$AF$5),0) | AH26: =IF(AND($AG26>0,AF26>$AF$6),1,0) | AI26: =IF(AH26=1,SUM($AH$15:AH26),"") | AJ26: =IF(AH26=1,$AG26/(1+$AF$8/2)^(AI26-1),0) | AK26: =IF(AH26=1,$AG26/(1+($AF$8+0.0001)/2)^(AI26-1),0) | AL26: =IF(AH26=1,$AG26/(1+($AF$8-0.0001)/2)^(AI26-1),0) | AM26: =IF(AND($AG26>0,AF26>$AF$7),1,0) | AN26: =IF(AM26=1,SUM($AM$15:AM26),"") | AO26: =IF(AM26=1,$AG26/(1+$AF$99/2)^(AN26-1),0) | AP26: =IF(AM26=1,$AG26/(1+($AF$99+0.0001)/2)^(AN26-1),0) | AQ26: =IF(AM26=1,$AG26/(1+($AF$99-0.0001)/2)^(AN26-1),0) | AR26: =IF(AM26=1,$AG26/(1+$AF$104/2)^(AN26-1),0) | AS26: =IF(AM26=1,$AG26/(1+($AF$104+0.0001)/2)^(AN26-1),0) | AT26: =IF(AM26=1,$AG26/(1+($AF$104-0.0001)/2)^(AN26-1),0) | AU26: =IF(AM26=1,$AG26/(1+$AF$109/2)^(AN26-1),0) | AV26: =IF(AND($AG26>0,AF26>$AF$6,AF26<=$AF$7),$AG26*(1+$AF$9*($AF$7-AF26)/365),0) | AW26: =IF(AM26=1,$AG26/(1+($AF$8+$AF$10/10000)/2)^(AN26-1),0) | AX26: =IF(AM26=1,$AG26/(1+($AF$8+메인!$A$96/10000)/2)^(AN26-1),0) | AY26: =IF(AM26=1,$AG26/(1+($AF$8+메인!$A$97/10000)/2)^(AN26-1),0) | AZ26: =IF(AM26=1,$AG26/(1+($AF$8+메인!$A$98/10000)/2)^(AN26-1),0) | BA26: =IF(AM26=1,$AG26/(1+($AF$8+메인!$A$99/10000)/2)^(AN26-1),0) | BB26: =IF(AM26=1,$AG26/(1+($AF$8+메인!$A$100/10000)/2)^(AN26-1),0) | BC26: =IF(AM26=1,$AG26/(1+($AF$8+메인!$A$101/10000)/2)^(AN26-1),0) | BD26: =IF(AM26=1,$AG26/(1+($AF$8+메인!$A$102/10000)/2)^(AN26-1),0) | BE26: =IF(AM26=1,$AG26/(1+($AF$8+메인!$A$103/10000)/2)^(AN26-1),0) | BF26: =IF(AM26=1,$AG26/(1+($AF$8+메인!$A$104/10000)/2)^(AN26-1),0)
... A76: 62 | B76: =EDATE($B$2,-6*(62-$A76)) | C76: =IF(AND(B76>$B$3,B76<=$B$2),IF(B76=$B$2,$B$5+100,$B$5),0) | D76: =IF(AND($C76>0,B76>$B$6),1,0) | E76: =IF(D76=1,SUM($D$15:D76),"") | F76: =IF(D76=1,$C76/(1+$B$8/2)^(E76-1),0) | G76: =IF(D76=1,$C76/(1+($B$8+0.0001)/2)^(E76-1),0) | H76: =IF(D76=1,$C76/(1+($B$8-0.0001)/2)^(E76-1),0) | I76: =IF(AND($C76>0,B76>$B$7),1,0) | J76: =IF(I76=1,SUM($I$15:I76),"") | K76: =IF(I76=1,$C76/(1+$B$99/2)^(J76-1),0) | L76: =IF(I76=1,$C76/(1+($B$99+0.0001)/2)^(J76-1),0) | M76: =IF(I76=1,$C76/(1+($B$99-0.0001)/2)^(J76-1),0) | N76: =IF(I76=1,$C76/(1+$B$104/2)^(J76-1),0) | O76: =IF(I76=1,$C76/(1+($B$104+0.0001)/2)^(J76-1),0) | P76: =IF(I76=1,$C76/(1+($B$104-0.0001)/2)^(J76-1),0) | Q76: =IF(I76=1,$C76/(1+$B$109/2)^(J76-1),0) | R76: =IF(AND($C76>0,B76>$B$6,B76<=$B$7),$C76*(1+$B$9*($B$7-B76)/365),0) | S76: =IF(I76=1,$C76/(1+($B$8+$B$10/10000)/2)^(J76-1),0) | T76: =IF(I76=1,$C76/(1+($B$8+메인!$A$96/10000)/2)^(J76-1),0) | U76: =IF(I76=1,$C76/(1+($B$8+메인!$A$97/10000)/2)^(J76-1),0) | V76: =IF(I76=1,$C76/(1+($B$8+메인!$A$98/10000)/2)^(J76-1),0) | W76: =IF(I76=1,$C76/(1+($B$8+메인!$A$99/10000)/2)^(J76-1),0) | X76: =IF(I76=1,$C76/(1+($B$8+메인!$A$100/10000)/2)^(J76-1),0) | Y76: =IF(I76=1,$C76/(1+($B$8+메인!$A$101/10000)/2)^(J76-1),0) | Z76: =IF(I76=1,$C76/(1+($B$8+메인!$A$102/10000)/2)^(J76-1),0) | AA76: =IF(I76=1,$C76/(1+($B$8+메인!$A$103/10000)/2)^(J76-1),0) | AB76: =IF(I76=1,$C76/(1+($B$8+메인!$A$104/10000)/2)^(J76-1),0) | AE76: 62 | AF76: =EDATE($AF$2,-6*(62-$AE76)) | AG76: =IF(AND(AF76>$AF$3,AF76<=$AF$2),IF(AF76=$AF$2,$AF$5+100,$AF$5),0) | AH76: =IF(AND($AG76>0,AF76>$AF$6),1,0) | AI76: =IF(AH76=1,SUM($AH$15:AH76),"") | AJ76: =IF(AH76=1,$AG76/(1+$AF$8/2)^(AI76-1),0) | AK76: =IF(AH76=1,$AG76/(1+($AF$8+0.0001)/2)^(AI76-1),0) | AL76: =IF(AH76=1,$AG76/(1+($AF$8-0.0001)/2)^(AI76-1),0) | AM76: =IF(AND($AG76>0,AF76>$AF$7),1,0) | AN76: =IF(AM76=1,SUM($AM$15:AM76),"") | AO76: =IF(AM76=1,$AG76/(1+$AF$99/2)^(AN76-1),0) | AP76: =IF(AM76=1,$AG76/(1+($AF$99+0.0001)/2)^(AN76-1),0) | AQ76: =IF(AM76=1,$AG76/(1+($AF$99-0.0001)/2)^(AN76-1),0) | AR76: =IF(AM76=1,$AG76/(1+$AF$104/2)^(AN76-1),0) | AS76: =IF(AM76=1,$AG76/(1+($AF$104+0.0001)/2)^(AN76-1),0) | AT76: =IF(AM76=1,$AG76/(1+($AF$104-0.0001)/2)^(AN76-1),0) | AU76: =IF(AM76=1,$AG76/(1+$AF$109/2)^(AN76-1),0) | AV76: =IF(AND($AG76>0,AF76>$AF$6,AF76<=$AF$7),$AG76*(1+$AF$9*($AF$7-AF76)/365),0) | AW76: =IF(AM76=1,$AG76/(1+($AF$8+$AF$10/10000)/2)^(AN76-1),0) | AX76: =IF(AM76=1,$AG76/(1+($AF$8+메인!$A$96/10000)/2)^(AN76-1),0) | AY76: =IF(AM76=1,$AG76/(1+($AF$8+메인!$A$97/10000)/2)^(AN76-1),0) | AZ76: =IF(AM76=1,$AG76/(1+($AF$8+메인!$A$98/10000)/2)^(AN76-1),0) | BA76: =IF(AM76=1,$AG76/(1+($AF$8+메인!$A$99/10000)/2)^(AN76-1),0) | BB76: =IF(AM76=1,$AG76/(1+($AF$8+메인!$A$100/10000)/2)^(AN76-1),0) | BC76: =IF(AM76=1,$AG76/(1+($AF$8+메인!$A$101/10000)/2)^(AN76-1),0) | BD76: =IF(AM76=1,$AG76/(1+($AF$8+메인!$A$102/10000)/2)^(AN76-1),0) | BE76: =IF(AM76=1,$AG76/(1+($AF$8+메인!$A$103/10000)/2)^(AN76-1),0) | BF76: =IF(AM76=1,$AG76/(1+($AF$8+메인!$A$104/10000)/2)^(AN76-1),0)
A78: ── 현물 (S0) ── | AE78: ── 현물 (S0) ──
A79: 잔존 이표횟수 | B79: =SUM(D15:D76) | AE79: 잔존 이표횟수 | AF79: =SUM(AH15:AH76)
A80: 차기 이표일 | B80: =INDEX(B15:B76,MATCH(1,D15:D76,0)) | AE80: 차기 이표일 | AF80: =INDEX(AF15:AF76,MATCH(1,AH15:AH76,0))
A81: 직전 이표일 | B81: =EDATE(B80,-6) | AE81: 직전 이표일 | AF81: =EDATE(AF80,-6)
A82: d | B82: =B80-B6 | AE82: d | AF82: =AF80-AF6
A83: T | B83: =B80-B81 | AE83: T | AF83: =AF80-AF81
A84: 현물단가(더티) | B84: =SUM(F15:F76)/(1+B8/2*B82/B83) | AE84: 현물단가(더티) | AF84: =SUM(AJ15:AJ76)/(1+AF8/2*AF82/AF83)
A85: P0 @+1bp | B85: =SUM(G15:G76)/(1+(B8+0.0001)/2*B82/B83) | AE85: P0 @+1bp | AF85: =SUM(AK15:AK76)/(1+(AF8+0.0001)/2*AF82/AF83)
A86: P0 @−1bp | B86: =SUM(H15:H76)/(1+(B8-0.0001)/2*B82/B83) | AE86: P0 @−1bp | AF86: =SUM(AL15:AL76)/(1+(AF8-0.0001)/2*AF82/AF83)
A87: 현물 BPV | B87: =(B86-B85)/2 | AE87: 현물 BPV | AF87: =(AF86-AF85)/2
A88: 수정듀레이션 | B88: =B87*10000/B84 | AE88: 수정듀레이션 | AF88: =AF87*10000/AF84
A90: ── 선도 (H) ── | AE90: ── 선도 (H) ──
A91: 선도 차기이표일 | B91: =INDEX(B15:B76,MATCH(1,I15:I76,0)) | AE91: 선도 차기이표일 | AF91: =INDEX(AF15:AF76,MATCH(1,AM15:AM76,0))
A92: 선도 직전이표일 | B92: =EDATE(B91,-6) | AE92: 선도 직전이표일 | AF92: =EDATE(AF91,-6)
A93: d_H | B93: =B91-B7 | AE93: d_H | AF93: =AF91-AF7
...
